Workbook

Sheet 한눈에 보기
A2: LoanSight AI WBS v1.2
A4: 버전 | B4: 변경 내용 | C4: 개정일 | D4: 작성자 | E4: 검토·승인자 | F4: 상태
A5: v1.0 | B5: 기존 계획 기준 56개 작업과 완료/미확인 상태·일정 정리. 기존 재무나침반 표기를 포함한 원본 보존. | C5: 46316 | D5: 김동혁 | E5: 미정 | F5: 이전본
A6: v1.1 | B6: LoanSight AI 기획안 v2.0·요구사항 v0.0.4 반영. 기존 56 ID 유지·13 작업 추가. 4개 업종/렌탈 제외·위험 사건 목표·6축 지표/단계·위험 패널·주석 추출/검출 상태 반영. R43/F41/U20 연결. | C6: 46319 | D6: 김동혁 | E6: 미정 | F6: 검토 대기
A8: 전체 항목 | B8: =COUNTA('작업 관리'!$A$9:$A$77) -> 69 | C8: 완료 확인 | D8: =COUNTIFS('작업 관리'!$J$9:$J$77,"완료 확인") -> 5 | E8: 진행 미확인 | F8: =COUNTIFS('작업 관리'!$G$9:$G$77,"미확인") -> 0 | G8: 예정 | H8: =COUNTIFS('작업 관리'!$G$9:$G$77,"예정") -> 49
A10: 단계별 계획
A11: 단계 | B11: 핵심 산출물 | C11: 필수 | D11: 보완 | E11: 마일스톤 | F11: 완료 확인 | G11: 시작 | H11: 마감
A12: 기획·범위 | B12: 기획안·4개 업종·산식·복합 위험 사건/미정 기준 | C12: =COUNTIFS('작업 관리'!$B$9:$B$77,$A12,'작업 관리'!$I$9:$I$77,"필수") -> 10 | D12: =COUNTIFS('작업 관리'!$B$9:$B$77,$A12,'작업 관리'!$I$9:$I$77,"보완") -> 0 | E12: =COUNTIFS('작업 관리'!$B$9:$B$77,$A12,'작업 관리'!$I$9:$I$77,"마일스톤") -> 1 | F12: =COUNTIFS('작업 관리'!$B$9:$B$77,$A12,'작업 관리'!$J$9:$J$77,"완료 확인") -> 5 | G12: =_xlfn.MINIFS('작업 관리'!$E$9:$E$77,'작업 관리'!$B$9:$B$77,$A12) -> #NAME? | H12: =_xlfn.MAXIFS('작업 관리'!$F$9:$F$77,'작업 관리'!$B$9:$B$77,$A12) -> #NAME?
A13: 데이터 | B13: 재무·주석·위험 사건 이력·계정 확보·검출 상태 | C13: =COUNTIFS('작업 관리'!$B$9:$B$77,$A13,'작업 관리'!$I$9:$I$77,"필수") -> 11 | D13: =COUNTIFS('작업 관리'!$B$9:$B$77,$A13,'작업 관리'!$I$9:$I$77,"보완") -> 0 | E13: =COUNTIFS('작업 관리'!$B$9:$B$77,$A13,'작업 관리'!$I$9:$I$77,"마일스톤") -> 0 | F13: =COUNTIFS('작업 관리'!$B$9:$B$77,$A13,'작업 관리'!$J$9:$J$77,"완료 확인") -> 0 | G13: =_xlfn.MINIFS('작업 관리'!$E$9:$E$77,'작업 관리'!$B$9:$B$77,$A13) -> #NAME? | H13: =_xlfn.MAXIFS('작업 관리'!$F$9:$F$77,'작업 관리'!$B$9:$B$77,$A13) -> #NAME?
A14: 분석·화면 | B14: 차입/영업순환·직접 입력·업종 변경·위험 패널 | C14: =COUNTIFS('작업 관리'!$B$9:$B$77,$A14,'작업 관리'!$I$9:$I$77,"필수") -> 12 | D14: =COUNTIFS('작업 관리'!$B$9:$B$77,$A14,'작업 관리'!$I$9:$I$77,"보완") -> 0 | E14: =COUNTIFS('작업 관리'!$B$9:$B$77,$A14,'작업 관리'!$I$9:$I$77,"마일스톤") -> 1 | F14: =COUNTIFS('작업 관리'!$B$9:$B$77,$A14,'작업 관리'!$J$9:$J$77,"완료 확인") -> 0 | G14: =_xlfn.MINIFS('작업 관리'!$E$9:$E$77,'작업 관리'!$B$9:$B$77,$A14) -> #NAME? | H14: =_xlfn.MAXIFS('작업 관리'!$F$9:$F$77,'작업 관리'!$B$9:$B$77,$A14) -> #NAME?
A15: AI·뉴스 | B15: 공통/업종 추출·정밀도/재현율·근거 요약/뉴스 보완 | C15: =COUNTIFS('작업 관리'!$B$9:$B$77,$A15,'작업 관리'!$I$9:$I$77,"필수") -> 7 | D15: =COUNTIFS('작업 관리'!$B$9:$B$77,$A15,'작업 관리'!$I$9:$I$77,"보완") -> 3 | E15: =COUNTIFS('작업 관리'!$B$9:$B$77,$A15,'작업 관리'!$I$9:$I$77,"마일스톤") -> 1 | F15: =COUNTIFS('작업 관리'!$B$9:$B$77,$A15,'작업 관리'!$J$9:$J$77,"완료 확인") -> 0 | G15: =_xlfn.MINIFS('작업 관리'!$E$9:$E$77,'작업 관리'!$B$9:$B$77,$A15) -> #NAME? | H15: =_xlfn.MAXIFS('작업 관리'!$F$9:$F$77,'작업 관리'!$B$9:$B$77,$A15) -> #NAME?
A16: 위험 사건 예측 | B16: 12개월 기준/결합 모델 비교·보정·시점 검증 | C16: =COUNTIFS('작업 관리'!$B$9:$B$77,$A16,'작업 관리'!$I$9:$I$77,"필수") -> 7 | D16: =COUNTIFS('작업 관리'!$B$9:$B$77,$A16,'작업 관리'!$I$9:$I$77,"보완") -> 0 | E16: =COUNTIFS('작업 관리'!$B$9:$B$77,$A16,'작업 관리'!$I$9:$I$77,"마일스톤") -> 1 | F16: =COUNTIFS('작업 관리'!$B$9:$B$77,$A16,'작업 관리'!$J$9:$J$77,"완료 확인") -> 0 | G16: =_xlfn.MINIFS('작업 관리'!$E$9:$E$77,'작업 관리'!$B$9:$B$77,$A16) -> #NAME? | H16: =_xlfn.MAXIFS('작업 관리'!$F$9:$F$77,'작업 관리'!$B$9:$B$77,$A16) -> #NAME?
A17: 통합·검증 | B17: 기능·원문·패널·모델 검수와 사용자 실험 | C17: =COUNTIFS('작업 관리'!$B$9:$B$77,$A17,'작업 관리'!$I$9:$I$77,"필수") -> 7 | D17: =COUNTIFS('작업 관리'!$B$9:$B$77,$A17,'작업 관리'!$I$9:$I$77,"보완") -> 0 | E17: =COUNTIFS('작업 관리'!$B$9:$B$77,$A17,'작업 관리'!$I$9:$I$77,"마일스톤") -> 1 | F17: =COUNTIFS('작업 관리'!$B$9:$B$77,$A17,'작업 관리'!$J$9:$J$77,"완료 확인") -> 0 | G17: =_xlfn.MINIFS('작업 관리'!$E$9:$E$77,'작업 관리'!$B$9:$B$77,$A17) -> #NAME? | H17: =_xlfn.MAXIFS('작업 관리'!$F$9:$F$77,'작업 관리'!$B$9:$B$77,$A17) -> #NAME?
A18: 제출·발표 | B18: 실행 안내·발표·시연영상·제출 | C18: =COUNTIFS('작업 관리'!$B$9:$B$77,$A18,'작업 관리'!$I$9:$I$77,"필수") -> 5 | D18: =COUNTIFS('작업 관리'!$B$9:$B$77,$A18,'작업 관리'!$I$9:$I$77,"보완") -> 0 | E18: =COUNTIFS('작업 관리'!$B$9:$B$77,$A18,'작업 관리'!$I$9:$I$77,"마일스톤") -> 2 | F18: =COUNTIFS('작업 관리'!$B$9:$B$77,$A18,'작업 관리'!$J$9:$J$77,"완료 확인") -> 0 | G18: =_xlfn.MINIFS('작업 관리'!$E$9:$E$77,'작업 관리'!$B$9:$B$77,$A18) -> #NAME? | H18: =_xlfn.MAXIFS('작업 관리'!$F$9:$F$77,'작업 관리'!$B$9:$B$77,$A18) -> #NAME?
A21: 주요 마일스톤
A22: ID | B22: 마일스톤 | C22: 담당 | D22: 마감 | E22: 상태 | F22: 선행 ID | G22: 산출물
A23: 1.M1 | B23: =INDEX('작업 관리'!$C$9:$C$77,MATCH($A23,'작업 관리'!$A$9:$A$77,0)) -> 업종·데이터·모델 설계 기준 확정 | C23: =INDEX('작업 관리'!$D$9:$D$77,MATCH($A23,'작업 관리'!$A$9:$A$77,0)) -> 김동혁 | D23: =INDEX('작업 관리'!$F$9:$F$77,MATCH($A23,'작업 관리'!$A$9:$A$77,0)) -> 46318 | E23: =INDEX('작업 관리'!$G$9:$G$77,MATCH($A23,'작업 관리'!$A$9:$A$77,0)) -> 진행중 | F23: =INDEX('완료 기준'!$D$9:$D$77,MATCH($A23,'완료 기준'!$A$9:$A$77,0)) -> 1.3, 1.5, 1.6, 1.7 | G23: =INDEX('완료 기준'!$E$9:$E$77,MATCH($A23,'완료 기준'!$A$9:$A$77,0)) -> 1차 범위 결정 기록
A24: 3.M2 | B24: =INDEX('작업 관리'!$C$9:$C$77,MATCH($A24,'작업 관리'!$A$9:$A$77,0)) -> 핵심 재무 기능 통합 완료 판단 | C24: =INDEX('작업 관리'!$D$9:$D$77,MATCH($A24,'작업 관리'!$A$9:$A$77,0)) -> 김동혁 | D24: =INDEX('작업 관리'!$F$9:$F$77,MATCH($A24,'작업 관리'!$A$9:$A$77,0)) -> 46325 | E24: =INDEX('작업 관리'!$G$9:$G$77,MATCH($A24,'작업 관리'!$A$9:$A$77,0)) -> 예정 | F24: =INDEX('완료 기준'!$D$9:$D$77,MATCH($A24,'완료 기준'!$A$9:$A$77,0)) -> 3.5, 3.7, 2.4, 3.10, 3.11, 3.12 | G24: =INDEX('완료 기준'!$E$9:$E$77,MATCH($A24,'완료 기준'!$A$9:$A$77,0)) -> 핵심 기능 확인 기록
A25: 4.M3 | B25: =INDEX('작업 관리'!$C$9:$C$77,MATCH($A25,'작업 관리'!$A$9:$A$77,0)) -> 주석 요약 검증과 제공 형식 확정 | C25: =INDEX('작업 관리'!$D$9:$D$77,MATCH($A25,'작업 관리'!$A$9:$A$77,0)) -> 김동혁 | D25: =INDEX('작업 관리'!$F$9:$F$77,MATCH($A25,'작업 관리'!$A$9:$A$77,0)) -> 46325 | E25: =INDEX('작업 관리'!$G$9:$G$77,MATCH($A25,'작업 관리'!$A$9:$A$77,0)) -> 예정 | F25: =INDEX('완료 기준'!$D$9:$D$77,MATCH($A25,'완료 기준'!$A$9:$A$77,0)) -> 4.5, 4.6, 4.10 | G25: =INDEX('완료 기준'!$E$9:$E$77,MATCH($A25,'완료 기준'!$A$9:$A$77,0)) -> 주석 검증·제공 형식 기록
A26: 7.M7 | B26: =INDEX('작업 관리'!$C$9:$C$77,MATCH($A26,'작업 관리'!$A$9:$A$77,0)) -> 위험 사건 모델·연동 검증 기준 고정 | C26: =INDEX('작업 관리'!$D$9:$D$77,MATCH($A26,'작업 관리'!$A$9:$A$77,0)) -> 김동혁 | D26: =INDEX('작업 관리'!$F$9:$F$77,MATCH($A26,'작업 관리'!$A$9:$A$77,0)) -> 46326 | E26: =INDEX('작업 관리'!$G$9:$G$77,MATCH($A26,'작업 관리'!$A$9:$A$77,0)) -> 예정 | F26: =INDEX('완료 기준'!$D$9:$D$77,MATCH($A26,'완료 기준'!$A$9:$A$77,0)) -> 7.2, 7.7 | G26: =INDEX('완료 기준'!$E$9:$E$77,MATCH($A26,'완료 기준'!$A$9:$A$77,0)) -> 검증 모델·연동 기준 버전
A27: 5.M4 | B27: =INDEX('작업 관리'!$C$9:$C$77,MATCH($A27,'작업 관리'!$A$9:$A$77,0)) -> 핵심 구현과 검증 마감 | C27: =INDEX('작업 관리'!$D$9:$D$77,MATCH($A27,'작업 관리'!$A$9:$A$77,0)) -> 김동혁 | D27: =INDEX('작업 관리'!$F$9:$F$77,MATCH($A27,'작업 관리'!$A$9:$A$77,0)) -> 46328 | E27: =INDEX('작업 관리'!$G$9:$G$77,MATCH($A27,'작업 관리'!$A$9:$A$77,0)) -> 예정 | F27: =INDEX('완료 기준'!$D$9:$D$77,MATCH($A27,'완료 기준'!$A$9:$A$77,0)) -> 5.6 | G27: =INDEX('완료 기준'!$E$9:$E$77,MATCH($A27,'완료 기준'!$A$9:$A$77,0)) -> 시연 기준 버전
A28: 6.M5 | B28: =INDEX('작업 관리'!$C$9:$C$77,MATCH($A28,'작업 관리'!$A$9:$A$77,0)) -> 최종 산출물 제출 | C28: =INDEX('작업 관리'!$D$9:$D$77,MATCH($A28,'작업 관리'!$A$9:$A$77,0)) -> 김동혁 | D28: =INDEX('작업 관리'!$F$9:$F$77,MATCH($A28,'작업 관리'!$A$9:$A$77,0)) -> 46331 | E28: =INDEX('작업 관리'!$G$9:$G$77,MATCH($A28,'작업 관리'!$A$9:$A$77,0)) -> 예정 | F28: =INDEX('완료 기준'!$D$9:$D$77,MATCH($A28,'완료 기준'!$A$9:$A$77,0)) -> 6.3, 6.4, 6.5 | G28: =INDEX('완료 기준'!$E$9:$E$77,MATCH($A28,'완료 기준'!$A$9:$A$77,0)) -> 제출 접수 확인
A29: 6.M6 | B29: =INDEX('작업 관리'!$C$9:$C$77,MATCH($A29,'작업 관리'!$A$9:$A$77,0)) -> 프로젝트 발표 | C29: =INDEX('작업 관리'!$D$9:$D$77,MATCH($A29,'작업 관리'!$A$9:$A$77,0)) -> 오준탁 | D29: =INDEX('작업 관리'!$F$9:$F$77,MATCH($A29,'작업 관리'!$A$9:$A$77,0)) -> 46331 | E29: =INDEX('작업 관리'!$G$9:$G$77,MATCH($A29,'작업 관리'!$A$9:$A$77,0)) -> 예정 | F29: =INDEX('완료 기준'!$D$9:$D$77,MATCH($A29,'완료 기준'!$A$9:$A$77,0)) -> 6.M5 | G29: =INDEX('완료 기준'!$E$9:$E$77,MATCH($A29,'완료 기준'!$A$9:$A$77,0)) -> 발표·질의응답 기록
A32: 문서 기준과 사용 안내
A34: 기준 문서
A35: 기획안 v2.0 · 요구사항/PRD/기능명세서 v0.0.4。WBS는 독립 버전 v1.0→v1.1로 개정했다. 기준은 기획안 v2.0, 요구사항/PRD/기능명세서 v0.0.4이며 문서별 버전 숫자를 임의로 통일하지 않는다.
A37: 계획과 실제
A38: 계획 기간 2026.10.21~11.05, 기획안 제출 11/05 09:00(N-U09 확인 필요)。69개(필수59·뉴스 보완3·마일스톤7)。기존56 ID 유지·13개 추가。완료2는 과거 기획안/발표 초안만 해당, 실제 진척 미확인41·예정26。
A40: 일정·담당 초안
A41: 원문 기간 창을 분해한 실행 초안이다. 기존 시작/종료·주담당·상태·진행률·완료근거를 보존하고 7.3만 업종 추출 선행조건에 맞춰 10/28 시작으로 조정했다. 같은 날 선행/후속은 당일 인수인계 전제。과거 미확인 항목은 팀 재확인이 필요하다. 개인별 공수·백업·최종 승인자는 미정。
A43: 범위·충돌 처리
A44: 제조·건설·도소매·부동산 임대 4개, 장비/물품 렌탈 제외。충돌 시 요구사항의 10/23 팀 결정을 우선한다. 기능15/정답지5는 논의 필요。추출40개사 인용·계정 점검 업종별5이상·모델 표본을 구분한다.
A46: 결정·검증
A47: 수치 임계값은 팀 가설이며 현직자 확인 전이다. 규칙 단계/모델 확률/담당자 체크는 분리한다. 검출/공시상 없음/미검출/추출 실패를 구분한다. 확장 N-R31/N-F28~29는 1.9/6.1의 범위 기록이며 개발 실행/완료로 세지 않는다.
A49: 표 사용
... A56: 기획안: fd0717b81e562166248006c3789d0b6f76dd888fa085ca70ae771f3731ab2715 요구사항: c788fdcccfd3d867a1f1812ed4bbe883d05b56afa52d91e650ea23f10582983c

Sheet 작업 관리
A2: LoanSight AI 작업 관리 v1.2
A4: 상태·진행률은 실제 확인값만 입력합니다. 완료는 진행률 100%와 완료근거를 함께 기록합니다.
A5: 기준: 기획안 v2.0·요구사항 v0.0.4。69개 작업。주담당·세부 날짜는 실행 초안, 미확인은 실제 진척 미확인。
A6: 같은 날의 선행·후속 작업은 당일 인수인계를 전제로 합니다. 마감일만으로 완료 처리하지 않습니다.
A8: ID | B8: 단계 | C8: 작업 | D8: 주담당 | E8: 시작 | F8: 마감 | G8: 상태 | H8: 진행률 | I8: 범위 | J8: 입력 확인
A9: 1.1 | B9: 기획·범위 | C9: 기획안 v1.0 확정본 정리 | D9: 김동혁 | E9: 46316 | F9: 46316 | G9: 완료 | H9: 1 | I9: 필수 | J9: =IF(G9="완료",IF(H9<>1,"진행률 확인",IF(COUNTBLANK(INDEX('완료 기준'!$G$9:$G$77,MATCH($A9,'완료 기준'!$A$9:$A$77,0)))>0,"완료근거 필요","완료 확인")),"") -> 완료 확인
A10: 1.2 | B10: 기획·범위 | C10: 기획 발표자료 v0.2 초안 보존 | D10: 오준탁 | E10: 46316 | F10: 46316 | G10: 완료 | H10: 1 | I10: 필수 | J10: =IF(G10="완료",IF(H10<>1,"진행률 확인",IF(COUNTBLANK(INDEX('완료 기준'!$G$9:$G$77,MATCH($A10,'완료 기준'!$A$9:$A$77,0)))>0,"완료근거 필요","완료 확인")),"") -> 완료 확인
A11: 1.3 | B11: 기획·범위 | C11: 범위와 역할 분담 합의 | D11: 김동혁 | E11: 46317 | F11: 46317 | G11: 완료 | H11: 1 | I11: 필수 | J11: =IF(G11="완료",IF(H11<>1,"진행률 확인",IF(COUNTBLANK(INDEX('완료 기준'!$G$9:$G$77,MATCH($A11,'완료 기준'!$A$9:$A$77,0)))>0,"완료근거 필요","완료 확인")),"") -> 완료 확인
A12: 1.4 | B12: 기획·범위 | C12: 확정 4개 업종과 수집 범위 점검 | D12: 김동민 | E12: 46317 | F12: 46318 | G12: 진행중 | I12: 필수 | J12: =IF(G12="완료",IF(H12<>1,"진행률 확인",IF(COUNTBLANK(INDEX('완료 기준'!$G$9:$G$77,MATCH($A12,'완료 기준'!$A$9:$A$77,0)))>0,"완료근거 필요","완료 확인")),"")
A13: 1.6 | B13: 기획·범위 | C13: 재무비율·계정·업종 계산 기준 정의 | D13: 오준탁 | E13: 46317 | F13: 46318 | G13: 완료 | H13: 1 | I13: 필수 | J13: =IF(G13="완료",IF(H13<>1,"진행률 확인",IF(COUNTBLANK(INDEX('완료 기준'!$G$9:$G$77,MATCH($A13,'완료 기준'!$A$9:$A$77,0)))>0,"완료근거 필요","완료 확인")),"") -> 완료 확인
A14: 1.7 | B14: 기획·범위 | C14: 상환·연체 위험 사건과 12개월 라벨 정의 | D14: 김동혁 | E14: 46317 | F14: 46318 | G14: 완료 | H14: 1 | I14: 필수 | J14: =IF(G14="완료",IF(H14<>1,"진행률 확인",IF(COUNTBLANK(INDEX('완료 기준'!$G$9:$G$77,MATCH($A14,'완료 기준'!$A$9:$A$77,0)))>0,"완료근거 필요","완료 확인")),"") -> 완료 확인
A15: 1.8 | B15: 기획·범위 | C15: 기획 발표자료에 최신 범위 반영 | D15: 오준탁 | E15: 46317 | F15: 46318 | G15: 진행중 | I15: 필수 | J15: =IF(G15="완료",IF(H15<>1,"진행률 확인",IF(COUNTBLANK(INDEX('완료 기준'!$G$9:$G$77,MATCH($A15,'완료 기준'!$A$9:$A$77,0)))>0,"완료근거 필요","완료 확인")),"")
A16: 1.5 | B16: 기획·범위 | C16: 기능 검증·원문 정답지 표본 선정 | D16: 최수인 | E16: 46318 | F16: 46318 | G16: 예정 | I16: 필수 | J16: =IF(G16="완료",IF(H16<>1,"진행률 확인",IF(COUNTBLANK(INDEX('완료 기준'!$G$9:$G$77,MATCH($A16,'완료 기준'!$A$9:$A$77,0)))>0,"완료근거 필요","완료 확인")),"")
A17: 1.M1 | B17: 기획·범위 | C17: 업종·데이터·모델 설계 기준 확정 | D17: 김동혁 | E17: 46318 | F17: 46318 | G17: 진행중 | I17: 마일스톤 | J17: =IF(G17="완료",IF(H17<>1,"진행률 확인",IF(COUNTBLANK(INDEX('완료 기준'!$G$9:$G$77,MATCH($A17,'완료 기준'!$A$9:$A$77,0)))>0,"완료근거 필요","완료 확인")),"")
A18: 1.9 | B18: 기획·범위 | C18: v2.0·v0.0.4 변경 및 미정 의사결정 정리 | D18: 김동혁 | E18: 46319 | F18: 46319 | G18: 진행중 | I18: 필수 | J18: =IF(G18="완료",IF(H18<>1,"진행률 확인",IF(COUNTBLANK(INDEX('완료 기준'!$G$9:$G$77,MATCH($A18,'완료 기준'!$A$9:$A$77,0)))>0,"완료근거 필요","완료 확인")),"")
A19: 1.10 | B19: 기획·범위 | C19: 6개 판단 축·업종 지표·단계 가설 검토 | D19: 오준탁 | E19: 46319 | F19: 46321 | G19: 예정 | I19: 필수 | J19: =IF(G19="완료",IF(H19<>1,"진행률 확인",IF(COUNTBLANK(INDEX('완료 기준'!$G$9:$G$77,MATCH($A19,'완료 기준'!$A$9:$A$77,0)))>0,"완료근거 필요","완료 확인")),"")
A20: 2.7 | B20: 데이터 | C20: 위험 사건 이력 수집과 원문 대조 | D20: 김동혁 | E20: 46318 | F20: 46319 | G20: 예정 | I20: 필수 | J20: =IF(G20="완료",IF(H20<>1,"진행률 확인",IF(COUNTBLANK(INDEX('완료 기준'!$G$9:$G$77,MATCH($A20,'완료 기준'!$A$9:$A$77,0)))>0,"완료근거 필요","완료 확인")),"")
A21: 2.1 | B21: 데이터 | C21: 재무·공시 수집과 출처 저장 | D21: 김동혁 | E21: 46319 | F21: 46320 | G21: 진행중 | I21: 필수 | J21: =IF(G21="완료",IF(H21<>1,"진행률 확인",IF(COUNTBLANK(INDEX('완료 기준'!$G$9:$G$77,MATCH($A21,'완료 기준'!$A$9:$A$77,0)))>0,"완료근거 필요","완료 확인")),"")
A22: 2.2 | B22: 데이터 | C22: 계정 매핑과 비교 기준 정렬 | D22: 김동민 | E22: 46319 | F22: 46320 | G22: 진행중 | I22: 필수 | J22: =IF(G22="완료",IF(H22<>1,"진행률 확인",IF(COUNTBLANK(INDEX('완료 기준'!$G$9:$G$77,MATCH($A22,'완료 기준'!$A$9:$A$77,0)))>0,"완료근거 필요","완료 확인")),"")
A23: 2.8 | B23: 데이터 | C23: 과거 재무·주석 학습자료 수집 | D23: 김동혁 | E23: 46319 | F23: 46320 | G23: 예정 | I23: 필수 | J23: =IF(G23="완료",IF(H23<>1,"진행률 확인",IF(COUNTBLANK(INDEX('완료 기준'!$G$9:$G$77,MATCH($A23,'완료 기준'!$A$9:$A$77,0)))>0,"완료근거 필요","완료 확인")),"")
A24: 2.5 | B24: 데이터 | C24: 원문 대조 정답지 작성 | D24: 최수인 | E24: 46319 | F24: 46321 | G24: 예정 | I24: 필수 | J24: =IF(G24="완료",IF(H24<>1,"진행률 확인",IF(COUNTBLANK(INDEX('완료 기준'!$G$9:$G$77,MATCH($A24,'완료 기준'!$A$9:$A$77,0)))>0,"완료근거 필요","완료 확인")),"")
A25: 2.3 | B25: 데이터 | C25: 주석 구간·교차참조·추출 표본 확보 | D25: 김동혁 | E25: 46320 | F25: 46320 | G25: 진행중 | I25: 필수 | J25: =IF(G25="완료",IF(H25<>1,"진행률 확인",IF(COUNTBLANK(INDEX('완료 기준'!$G$9:$G$77,MATCH($A25,'완료 기준'!$A$9:$A$77,0)))>0,"완료근거 필요","완료 확인")),"")
A26: 2.9 | B26: 데이터 | C26: 12개월 라벨과 관측기간 구성 | D26: 김동민 | E26: 46320 | F26: 46321 | G26: 진행중 | I26: 필수 | J26: =IF(G26="완료",IF(H26<>1,"진행률 확인",IF(COUNTBLANK(INDEX('완료 기준'!$G$9:$G$77,MATCH($A26,'완료 기준'!$A$9:$A$77,0)))>0,"완료근거 필요","완료 확인")),"")
... A77: 6.M6 | B77: 제출·발표 | C77: 프로젝트 발표 | D77: 오준탁 | E77: 46331 | F77: 46331 | G77: 예정 | I77: 마일스톤 | J77: =IF(G77="완료",IF(H77<>1,"진행률 확인",IF(COUNTBLANK(INDEX('완료 기준'!$G$9:$G$77,MATCH($A77,'완료 기준'!$A$9:$A$77,0)))>0,"완료근거 필요","완료 확인")),"")

Sheet 일정
A2: LoanSight AI 일정 v1.2
A4: 2026년 10월 21일~11월 5일 계획. 셀 색은 작업 관리의 시작·마감일을 따라 바뀝니다.
A5: 파랑은 작업 기간, 초록은 완료 작업, 보라는 마일스톤입니다. 옅은 회색 열은 주말입니다.
A6: 달력일 기준 계획입니다. 교육 일정과 팀 가용 시간을 확인한 뒤 세부 날짜를 확정합니다.
D7: 10월 | O7: 11월
A8: ID | B8: 작업 | C8: 담당 | D8: 46316 | E8: 46317 | F8: 46318 | G8: 46319 | H8: 46320 | I8: 46321 | J8: 46322 | K8: 46323 | L8: 46324 | M8: 46325 | N8: 46326 | O8: 46327 | P8: 46328 | Q8: 46329 | R8: 46330 | S8: 46331
A9: ='작업 관리'!A9 -> 1.1 | B9: ='작업 관리'!C9 -> 기획안 v1.0 확정본 정리 | C9: ='작업 관리'!D9 -> 김동혁 | D9: =IF(AND(D$8>='작업 관리'!$E9,D$8<='작업 관리'!$F9),IF('작업 관리'!$I9="마일스톤",3,IF('작업 관리'!$G9="완료",2,1)),"") -> 2 | E9: =IF(AND(E$8>='작업 관리'!$E9,E$8<='작업 관리'!$F9),IF('작업 관리'!$I9="마일스톤",3,IF('작업 관리'!$G9="완료",2,1)),"") | F9: =IF(AND(F$8>='작업 관리'!$E9,F$8<='작업 관리'!$F9),IF('작업 관리'!$I9="마일스톤",3,IF('작업 관리'!$G9="완료",2,1)),"") | G9: =IF(AND(G$8>='작업 관리'!$E9,G$8<='작업 관리'!$F9),IF('작업 관리'!$I9="마일스톤",3,IF('작업 관리'!$G9="완료",2,1)),"") | H9: =IF(AND(H$8>='작업 관리'!$E9,H$8<='작업 관리'!$F9),IF('작업 관리'!$I9="마일스톤",3,IF('작업 관리'!$G9="완료",2,1)),"") | I9: =IF(AND(I$8>='작업 관리'!$E9,I$8<='작업 관리'!$F9),IF('작업 관리'!$I9="마일스톤",3,IF('작업 관리'!$G9="완료",2,1)),"") | J9: =IF(AND(J$8>='작업 관리'!$E9,J$8<='작업 관리'!$F9),IF('작업 관리'!$I9="마일스톤",3,IF('작업 관리'!$G9="완료",2,1)),"") | K9: =IF(AND(K$8>='작업 관리'!$E9,K$8<='작업 관리'!$F9),IF('작업 관리'!$I9="마일스톤",3,IF('작업 관리'!$G9="완료",2,1)),"") | ... S9: =IF(AND(S$8>='작업 관리'!$E9,S$8<='작업 관리'!$F9),IF('작업 관리'!$I9="마일스톤",3,IF('작업 관리'!$G9="완료",2,1)),"")
A10: ='작업 관리'!A10 -> 1.2 | B10: ='작업 관리'!C10 -> 기획 발표자료 v0.2 초안 보존 | C10: ='작업 관리'!D10 -> 오준탁 | D10: =IF(AND(D$8>='작업 관리'!$E10,D$8<='작업 관리'!$F10),IF('작업 관리'!$I10="마일스톤",3,IF('작업 관리'!$G10="완료",2,1)),"") -> 2 | E10: =IF(AND(E$8>='작업 관리'!$E10,E$8<='작업 관리'!$F10),IF('작업 관리'!$I10="마일스톤",3,IF('작업 관리'!$G10="완료",2,1)),"") | F10: =IF(AND(F$8>='작업 관리'!$E10,F$8<='작업 관리'!$F10),IF('작업 관리'!$I10="마일스톤",3,IF('작업 관리'!$G10="완료",2,1)),"") | G10: =IF(AND(G$8>='작업 관리'!$E10,G$8<='작업 관리'!$F10),IF('작업 관리'!$I10="마일스톤",3,IF('작업 관리'!$G10="완료",2,1)),"") | H10: =IF(AND(H$8>='작업 관리'!$E10,H$8<='작업 관리'!$F10),IF('작업 관리'!$I10="마일스톤",3,IF('작업 관리'!$G10="완료",2,1)),"") | I10: =IF(AND(I$8>='작업 관리'!$E10,I$8<='작업 관리'!$F10),IF('작업 관리'!$I10="마일스톤",3,IF('작업 관리'!$G10="완료",2,1)),"") | J10: =IF(AND(J$8>='작업 관리'!$E10,J$8<='작업 관리'!$F10),IF('작업 관리'!$I10="마일스톤",3,IF('작업 관리'!$G10="완료",2,1)),"") | K10: =IF(AND(K$8>='작업 관리'!$E10,K$8<='작업 관리'!$F10),IF('작업 관리'!$I10="마일스톤",3,IF('작업 관리'!$G10="완료",2,1)),"") | ... S10: =IF(AND(S$8>='작업 관리'!$E10,S$8<='작업 관리'!$F10),IF('작업 관리'!$I10="마일스톤",3,IF('작업 관리'!$G10="완료",2,1)),"")
A11: ='작업 관리'!A11 -> 1.3 | B11: ='작업 관리'!C11 -> 범위와 역할 분담 합의 | C11: ='작업 관리'!D11 -> 김동혁 | D11: =IF(AND(D$8>='작업 관리'!$E11,D$8<='작업 관리'!$F11),IF('작업 관리'!$I11="마일스톤",3,IF('작업 관리'!$G11="완료",2,1)),"") | E11: =IF(AND(E$8>='작업 관리'!$E11,E$8<='작업 관리'!$F11),IF('작업 관리'!$I11="마일스톤",3,IF('작업 관리'!$G11="완료",2,1)),"") -> 2 | F11: =IF(AND(F$8>='작업 관리'!$E11,F$8<='작업 관리'!$F11),IF('작업 관리'!$I11="마일스톤",3,IF('작업 관리'!$G11="완료",2,1)),"") | G11: =IF(AND(G$8>='작업 관리'!$E11,G$8<='작업 관리'!$F11),IF('작업 관리'!$I11="마일스톤",3,IF('작업 관리'!$G11="완료",2,1)),"") | H11: =IF(AND(H$8>='작업 관리'!$E11,H$8<='작업 관리'!$F11),IF('작업 관리'!$I11="마일스톤",3,IF('작업 관리'!$G11="완료",2,1)),"") | I11: =IF(AND(I$8>='작업 관리'!$E11,I$8<='작업 관리'!$F11),IF('작업 관리'!$I11="마일스톤",3,IF('작업 관리'!$G11="완료",2,1)),"") | J11: =IF(AND(J$8>='작업 관리'!$E11,J$8<='작업 관리'!$F11),IF('작업 관리'!$I11="마일스톤",3,IF('작업 관리'!$G11="완료",2,1)),"") | K11: =IF(AND(K$8>='작업 관리'!$E11,K$8<='작업 관리'!$F11),IF('작업 관리'!$I11="마일스톤",3,IF('작업 관리'!$G11="완료",2,1)),"") | ... S11: =IF(AND(S$8>='작업 관리'!$E11,S$8<='작업 관리'!$F11),IF('작업 관리'!$I11="마일스톤",3,IF('작업 관리'!$G11="완료",2,1)),"")
A12: ='작업 관리'!A12 -> 1.4 | B12: ='작업 관리'!C12 -> 확정 4개 업종과 수집 범위 점검 | C12: ='작업 관리'!D12 -> 김동민 | D12: =IF(AND(D$8>='작업 관리'!$E12,D$8<='작업 관리'!$F12),IF('작업 관리'!$I12="마일스톤",3,IF('작업 관리'!$G12="완료",2,1)),"") | E12: =IF(AND(E$8>='작업 관리'!$E12,E$8<='작업 관리'!$F12),IF('작업 관리'!$I12="마일스톤",3,IF('작업 관리'!$G12="완료",2,1)),"") -> 1 | F12: =IF(AND(F$8>='작업 관리'!$E12,F$8<='작업 관리'!$F12),IF('작업 관리'!$I12="마일스톤",3,IF('작업 관리'!$G12="완료",2,1)),"") -> 1 | G12: =IF(AND(G$8>='작업 관리'!$E12,G$8<='작업 관리'!$F12),IF('작업 관리'!$I12="마일스톤",3,IF('작업 관리'!$G12="완료",2,1)),"") | H12: =IF(AND(H$8>='작업 관리'!$E12,H$8<='작업 관리'!$F12),IF('작업 관리'!$I12="마일스톤",3,IF('작업 관리'!$G12="완료",2,1)),"") | I12: =IF(AND(I$8>='작업 관리'!$E12,I$8<='작업 관리'!$F12),IF('작업 관리'!$I12="마일스톤",3,IF('작업 관리'!$G12="완료",2,1)),"") | J12: =IF(AND(J$8>='작업 관리'!$E12,J$8<='작업 관리'!$F12),IF('작업 관리'!$I12="마일스톤",3,IF('작업 관리'!$G12="완료",2,1)),"") | K12: =IF(AND(K$8>='작업 관리'!$E12,K$8<='작업 관리'!$F12),IF('작업 관리'!$I12="마일스톤",3,IF('작업 관리'!$G12="완료",2,1)),"") | ... S12: =IF(AND(S$8>='작업 관리'!$E12,S$8<='작업 관리'!$F12),IF('작업 관리'!$I12="마일스톤",3,IF('작업 관리'!$G12="완료",2,1)),"")
A13: ='작업 관리'!A13 -> 1.6 | B13: ='작업 관리'!C13 -> 재무비율·계정·업종 계산 기준 정의 | C13: ='작업 관리'!D13 -> 오준탁 | D13: =IF(AND(D$8>='작업 관리'!$E13,D$8<='작업 관리'!$F13),IF('작업 관리'!$I13="마일스톤",3,IF('작업 관리'!$G13="완료",2,1)),"") | E13: =IF(AND(E$8>='작업 관리'!$E13,E$8<='작업 관리'!$F13),IF('작업 관리'!$I13="마일스톤",3,IF('작업 관리'!$G13="완료",2,1)),"") -> 2 | F13: =IF(AND(F$8>='작업 관리'!$E13,F$8<='작업 관리'!$F13),IF('작업 관리'!$I13="마일스톤",3,IF('작업 관리'!$G13="완료",2,1)),"") -> 2 | G13: =IF(AND(G$8>='작업 관리'!$E13,G$8<='작업 관리'!$F13),IF('작업 관리'!$I13="마일스톤",3,IF('작업 관리'!$G13="완료",2,1)),"") | H13: =IF(AND(H$8>='작업 관리'!$E13,H$8<='작업 관리'!$F13),IF('작업 관리'!$I13="마일스톤",3,IF('작업 관리'!$G13="완료",2,1)),"") | I13: =IF(AND(I$8>='작업 관리'!$E13,I$8<='작업 관리'!$F13),IF('작업 관리'!$I13="마일스톤",3,IF('작업 관리'!$G13="완료",2,1)),"") | J13: =IF(AND(J$8>='작업 관리'!$E13,J$8<='작업 관리'!$F13),IF('작업 관리'!$I13="마일스톤",3,IF('작업 관리'!$G13="완료",2,1)),"") | K13: =IF(AND(K$8>='작업 관리'!$E13,K$8<='작업 관리'!$F13),IF('작업 관리'!$I13="마일스톤",3,IF('작업 관리'!$G13="완료",2,1)),"") | ... S13: =IF(AND(S$8>='작업 관리'!$E13,S$8<='작업 관리'!$F13),IF('작업 관리'!$I13="마일스톤",3,IF('작업 관리'!$G13="완료",2,1)),"")
A14: ='작업 관리'!A14 -> 1.7 | B14: ='작업 관리'!C14 -> 상환·연체 위험 사건과 12개월 라벨 정의 | C14: ='작업 관리'!D14 -> 김동혁 | D14: =IF(AND(D$8>='작업 관리'!$E14,D$8<='작업 관리'!$F14),IF('작업 관리'!$I14="마일스톤",3,IF('작업 관리'!$G14="완료",2,1)),"") | E14: =IF(AND(E$8>='작업 관리'!$E14,E$8<='작업 관리'!$F14),IF('작업 관리'!$I14="마일스톤",3,IF('작업 관리'!$G14="완료",2,1)),"") -> 2 | F14: =IF(AND(F$8>='작업 관리'!$E14,F$8<='작업 관리'!$F14),IF('작업 관리'!$I14="마일스톤",3,IF('작업 관리'!$G14="완료",2,1)),"") -> 2 | G14: =IF(AND(G$8>='작업 관리'!$E14,G$8<='작업 관리'!$F14),IF('작업 관리'!$I14="마일스톤",3,IF('작업 관리'!$G14="완료",2,1)),"") | H14: =IF(AND(H$8>='작업 관리'!$E14,H$8<='작업 관리'!$F14),IF('작업 관리'!$I14="마일스톤",3,IF('작업 관리'!$G14="완료",2,1)),"") | I14: =IF(AND(I$8>='작업 관리'!$E14,I$8<='작업 관리'!$F14),IF('작업 관리'!$I14="마일스톤",3,IF('작업 관리'!$G14="완료",2,1)),"") | J14: =IF(AND(J$8>='작업 관리'!$E14,J$8<='작업 관리'!$F14),IF('작업 관리'!$I14="마일스톤",3,IF('작업 관리'!$G14="완료",2,1)),"") | K14: =IF(AND(K$8>='작업 관리'!$E14,K$8<='작업 관리'!$F14),IF('작업 관리'!$I14="마일스톤",3,IF('작업 관리'!$G14="완료",2,1)),"") | ... S14: =IF(AND(S$8>='작업 관리'!$E14,S$8<='작업 관리'!$F14),IF('작업 관리'!$I14="마일스톤",3,IF('작업 관리'!$G14="완료",2,1)),"")
A15: ='작업 관리'!A15 -> 1.8 | B15: ='작업 관리'!C15 -> 기획 발표자료에 최신 범위 반영 | C15: ='작업 관리'!D15 -> 오준탁 | D15: =IF(AND(D$8>='작업 관리'!$E15,D$8<='작업 관리'!$F15),IF('작업 관리'!$I15="마일스톤",3,IF('작업 관리'!$G15="완료",2,1)),"") | E15: =IF(AND(E$8>='작업 관리'!$E15,E$8<='작업 관리'!$F15),IF('작업 관리'!$I15="마일스톤",3,IF('작업 관리'!$G15="완료",2,1)),"") -> 1 | F15: =IF(AND(F$8>='작업 관리'!$E15,F$8<='작업 관리'!$F15),IF('작업 관리'!$I15="마일스톤",3,IF('작업 관리'!$G15="완료",2,1)),"") -> 1 | G15: =IF(AND(G$8>='작업 관리'!$E15,G$8<='작업 관리'!$F15),IF('작업 관리'!$I15="마일스톤",3,IF('작업 관리'!$G15="완료",2,1)),"") | H15: =IF(AND(H$8>='작업 관리'!$E15,H$8<='작업 관리'!$F15),IF('작업 관리'!$I15="마일스톤",3,IF('작업 관리'!$G15="완료",2,1)),"") | I15: =IF(AND(I$8>='작업 관리'!$E15,I$8<='작업 관리'!$F15),IF('작업 관리'!$I15="마일스톤",3,IF('작업 관리'!$G15="완료",2,1)),"") | J15: =IF(AND(J$8>='작업 관리'!$E15,J$8<='작업 관리'!$F15),IF('작업 관리'!$I15="마일스톤",3,IF('작업 관리'!$G15="완료",2,1)),"") | K15: =IF(AND(K$8>='작업 관리'!$E15,K$8<='작업 관리'!$F15),IF('작업 관리'!$I15="마일스톤",3,IF('작업 관리'!$G15="완료",2,1)),"") | ... S15: =IF(AND(S$8>='작업 관리'!$E15,S$8<='작업 관리'!$F15),IF('작업 관리'!$I15="마일스톤",3,IF('작업 관리'!$G15="완료",2,1)),"")
A16: ='작업 관리'!A16 -> 1.5 | B16: ='작업 관리'!C16 -> 기능 검증·원문 정답지 표본 선정 | C16: ='작업 관리'!D16 -> 최수인 | D16: =IF(AND(D$8>='작업 관리'!$E16,D$8<='작업 관리'!$F16),IF('작업 관리'!$I16="마일스톤",3,IF('작업 관리'!$G16="완료",2,1)),"") | E16: =IF(AND(E$8>='작업 관리'!$E16,E$8<='작업 관리'!$F16),IF('작업 관리'!$I16="마일스톤",3,IF('작업 관리'!$G16="완료",2,1)),"") | F16: =IF(AND(F$8>='작업 관리'!$E16,F$8<='작업 관리'!$F16),IF('작업 관리'!$I16="마일스톤",3,IF('작업 관리'!$G16="완료",2,1)),"") -> 1 | G16: =IF(AND(G$8>='작업 관리'!$E16,G$8<='작업 관리'!$F16),IF('작업 관리'!$I16="마일스톤",3,IF('작업 관리'!$G16="완료",2,1)),"") | H16: =IF(AND(H$8>='작업 관리'!$E16,H$8<='작업 관리'!$F16),IF('작업 관리'!$I16="마일스톤",3,IF('작업 관리'!$G16="완료",2,1)),"") | I16: =IF(AND(I$8>='작업 관리'!$E16,I$8<='작업 관리'!$F16),IF('작업 관리'!$I16="마일스톤",3,IF('작업 관리'!$G16="완료",2,1)),"") | J16: =IF(AND(J$8>='작업 관리'!$E16,J$8<='작업 관리'!$F16),IF('작업 관리'!$I16="마일스톤",3,IF('작업 관리'!$G16="완료",2,1)),"") | K16: =IF(AND(K$8>='작업 관리'!$E16,K$8<='작업 관리'!$F16),IF('작업 관리'!$I16="마일스톤",3,IF('작업 관리'!$G16="완료",2,1)),"") | ... S16: =IF(AND(S$8>='작업 관리'!$E16,S$8<='작업 관리'!$F16),IF('작업 관리'!$I16="마일스톤",3,IF('작업 관리'!$G16="완료",2,1)),"")
A17: ='작업 관리'!A17 -> 1.M1 | B17: ='작업 관리'!C17 -> 업종·데이터·모델 설계 기준 확정 | C17: ='작업 관리'!D17 -> 김동혁 | D17: =IF(AND(D$8>='작업 관리'!$E17,D$8<='작업 관리'!$F17),IF('작업 관리'!$I17="마일스톤",3,IF('작업 관리'!$G17="완료",2,1)),"") | E17: =IF(AND(E$8>='작업 관리'!$E17,E$8<='작업 관리'!$F17),IF('작업 관리'!$I17="마일스톤",3,IF('작업 관리'!$G17="완료",2,1)),"") | F17: =IF(AND(F$8>='작업 관리'!$E17,F$8<='작업 관리'!$F17),IF('작업 관리'!$I17="마일스톤",3,IF('작업 관리'!$G17="완료",2,1)),"") -> 3 | G17: =IF(AND(G$8>='작업 관리'!$E17,G$8<='작업 관리'!$F17),IF('작업 관리'!$I17="마일스톤",3,IF('작업 관리'!$G17="완료",2,1)),"") | H17: =IF(AND(H$8>='작업 관리'!$E17,H$8<='작업 관리'!$F17),IF('작업 관리'!$I17="마일스톤",3,IF('작업 관리'!$G17="완료",2,1)),"") | I17: =IF(AND(I$8>='작업 관리'!$E17,I$8<='작업 관리'!$F17),IF('작업 관리'!$I17="마일스톤",3,IF('작업 관리'!$G17="완료",2,1)),"") | J17: =IF(AND(J$8>='작업 관리'!$E17,J$8<='작업 관리'!$F17),IF('작업 관리'!$I17="마일스톤",3,IF('작업 관리'!$G17="완료",2,1)),"") | K17: =IF(AND(K$8>='작업 관리'!$E17,K$8<='작업 관리'!$F17),IF('작업 관리'!$I17="마일스톤",3,IF('작업 관리'!$G17="완료",2,1)),"") | ... S17: =IF(AND(S$8>='작업 관리'!$E17,S$8<='작업 관리'!$F17),IF('작업 관리'!$I17="마일스톤",3,IF('작업 관리'!$G17="완료",2,1)),"")
A18: ='작업 관리'!A18 -> 1.9 | B18: ='작업 관리'!C18 -> v2.0·v0.0.4 변경 및 미정 의사결정 정리 | C18: ='작업 관리'!D18 -> 김동혁 | D18: =IF(AND(D$8>='작업 관리'!$E18,D$8<='작업 관리'!$F18),IF('작업 관리'!$I18="마일스톤",3,IF('작업 관리'!$G18="완료",2,1)),"") | E18: =IF(AND(E$8>='작업 관리'!$E18,E$8<='작업 관리'!$F18),IF('작업 관리'!$I18="마일스톤",3,IF('작업 관리'!$G18="완료",2,1)),"") | F18: =IF(AND(F$8>='작업 관리'!$E18,F$8<='작업 관리'!$F18),IF('작업 관리'!$I18="마일스톤",3,IF('작업 관리'!$G18="완료",2,1)),"") | G18: =IF(AND(G$8>='작업 관리'!$E18,G$8<='작업 관리'!$F18),IF('작업 관리'!$I18="마일스톤",3,IF('작업 관리'!$G18="완료",2,1)),"") -> 1 | H18: =IF(AND(H$8>='작업 관리'!$E18,H$8<='작업 관리'!$F18),IF('작업 관리'!$I18="마일스톤",3,IF('작업 관리'!$G18="완료",2,1)),"") | I18: =IF(AND(I$8>='작업 관리'!$E18,I$8<='작업 관리'!$F18),IF('작업 관리'!$I18="마일스톤",3,IF('작업 관리'!$G18="완료",2,1)),"") | J18: =IF(AND(J$8>='작업 관리'!$E18,J$8<='작업 관리'!$F18),IF('작업 관리'!$I18="마일스톤",3,IF('작업 관리'!$G18="완료",2,1)),"") | K18: =IF(AND(K$8>='작업 관리'!$E18,K$8<='작업 관리'!$F18),IF('작업 관리'!$I18="마일스톤",3,IF('작업 관리'!$G18="완료",2,1)),"") | ... S18: =IF(AND(S$8>='작업 관리'!$E18,S$8<='작업 관리'!$F18),IF('작업 관리'!$I18="마일스톤",3,IF('작업 관리'!$G18="완료",2,1)),"")
A19: ='작업 관리'!A19 -> 1.10 | B19: ='작업 관리'!C19 -> 6개 판단 축·업종 지표·단계 가설 검토 | C19: ='작업 관리'!D19 -> 오준탁 | D19: =IF(AND(D$8>='작업 관리'!$E19,D$8<='작업 관리'!$F19),IF('작업 관리'!$I19="마일스톤",3,IF('작업 관리'!$G19="완료",2,1)),"") | E19: =IF(AND(E$8>='작업 관리'!$E19,E$8<='작업 관리'!$F19),IF('작업 관리'!$I19="마일스톤",3,IF('작업 관리'!$G19="완료",2,1)),"") | F19: =IF(AND(F$8>='작업 관리'!$E19,F$8<='작업 관리'!$F19),IF('작업 관리'!$I19="마일스톤",3,IF('작업 관리'!$G19="완료",2,1)),"") | G19: =IF(AND(G$8>='작업 관리'!$E19,G$8<='작업 관리'!$F19),IF('작업 관리'!$I19="마일스톤",3,IF('작업 관리'!$G19="완료",2,1)),"") -> 1 | H19: =IF(AND(H$8>='작업 관리'!$E19,H$8<='작업 관리'!$F19),IF('작업 관리'!$I19="마일스톤",3,IF('작업 관리'!$G19="완료",2,1)),"") -> 1 | I19: =IF(AND(I$8>='작업 관리'!$E19,I$8<='작업 관리'!$F19),IF('작업 관리'!$I19="마일스톤",3,IF('작업 관리'!$G19="완료",2,1)),"") -> 1 | J19: =IF(AND(J$8>='작업 관리'!$E19,J$8<='작업 관리'!$F19),IF('작업 관리'!$I19="마일스톤",3,IF('작업 관리'!$G19="완료",2,1)),"") | K19: =IF(AND(K$8>='작업 관리'!$E19,K$8<='작업 관리'!$F19),IF('작업 관리'!$I19="마일스톤",3,IF('작업 관리'!$G19="완료",2,1)),"") | ... S19: =IF(AND(S$8>='작업 관리'!$E19,S$8<='작업 관리'!$F19),IF('작업 관리'!$I19="마일스톤",3,IF('작업 관리'!$G19="완료",2,1)),"")
A20: ='작업 관리'!A20 -> 2.7 | B20: ='작업 관리'!C20 -> 위험 사건 이력 수집과 원문 대조 | C20: ='작업 관리'!D20 -> 김동혁 | D20: =IF(AND(D$8>='작업 관리'!$E20,D$8<='작업 관리'!$F20),IF('작업 관리'!$I20="마일스톤",3,IF('작업 관리'!$G20="완료",2,1)),"") | E20: =IF(AND(E$8>='작업 관리'!$E20,E$8<='작업 관리'!$F20),IF('작업 관리'!$I20="마일스톤",3,IF('작업 관리'!$G20="완료",2,1)),"") | F20: =IF(AND(F$8>='작업 관리'!$E20,F$8<='작업 관리'!$F20),IF('작업 관리'!$I20="마일스톤",3,IF('작업 관리'!$G20="완료",2,1)),"") -> 1 | G20: =IF(AND(G$8>='작업 관리'!$E20,G$8<='작업 관리'!$F20),IF('작업 관리'!$I20="마일스톤",3,IF('작업 관리'!$G20="완료",2,1)),"") -> 1 | H20: =IF(AND(H$8>='작업 관리'!$E20,H$8<='작업 관리'!$F20),IF('작업 관리'!$I20="마일스톤",3,IF('작업 관리'!$G20="완료",2,1)),"") | I20: =IF(AND(I$8>='작업 관리'!$E20,I$8<='작업 관리'!$F20),IF('작업 관리'!$I20="마일스톤",3,IF('작업 관리'!$G20="완료",2,1)),"") | J20: =IF(AND(J$8>='작업 관리'!$E20,J$8<='작업 관리'!$F20),IF('작업 관리'!$I20="마일스톤",3,IF('작업 관리'!$G20="완료",2,1)),"") | K20: =IF(AND(K$8>='작업 관리'!$E20,K$8<='작업 관리'!$F20),IF('작업 관리'!$I20="마일스톤",3,IF('작업 관리'!$G20="완료",2,1)),"") | ... S20: =IF(AND(S$8>='작업 관리'!$E20,S$8<='작업 관리'!$F20),IF('작업 관리'!$I20="마일스톤",3,IF('작업 관리'!$G20="완료",2,1)),"")
... A77: ='작업 관리'!A77 -> 6.M6 | B77: ='작업 관리'!C77 -> 프로젝트 발표 | C77: ='작업 관리'!D77 -> 오준탁 | D77: =IF(AND(D$8>='작업 관리'!$E77,D$8<='작업 관리'!$F77),IF('작업 관리'!$I77="마일스톤",3,IF('작업 관리'!$G77="완료",2,1)),"") | E77: =IF(AND(E$8>='작업 관리'!$E77,E$8<='작업 관리'!$F77),IF('작업 관리'!$I77="마일스톤",3,IF('작업 관리'!$G77="완료",2,1)),"") | F77: =IF(AND(F$8>='작업 관리'!$E77,F$8<='작업 관리'!$F77),IF('작업 관리'!$I77="마일스톤",3,IF('작업 관리'!$G77="완료",2,1)),"") | G77: =IF(AND(G$8>='작업 관리'!$E77,G$8<='작업 관리'!$F77),IF('작업 관리'!$I77="마일스톤",3,IF('작업 관리'!$G77="완료",2,1)),"") | H77: =IF(AND(H$8>='작업 관리'!$E77,H$8<='작업 관리'!$F77),IF('작업 관리'!$I77="마일스톤",3,IF('작업 관리'!$G77="완료",2,1)),"") | I77: =IF(AND(I$8>='작업 관리'!$E77,I$8<='작업 관리'!$F77),IF('작업 관리'!$I77="마일스톤",3,IF('작업 관리'!$G77="완료",2,1)),"") | J77: =IF(AND(J$8>='작업 관리'!$E77,J$8<='작업 관리'!$F77),IF('작업 관리'!$I77="마일스톤",3,IF('작업 관리'!$G77="완료",2,1)),"") | K77: =IF(AND(K$8>='작업 관리'!$E77,K$8<='작업 관리'!$F77),IF('작업 관리'!$I77="마일스톤",3,IF('작업 관리'!$G77="완료",2,1)),"") | ... S77: =IF(AND(S$8>='작업 관리'!$E77,S$8<='작업 관리'!$F77),IF('작업 관리'!$I77="마일스톤",3,IF('작업 관리'!$G77="완료",2,1)),"") -> 3

Sheet 완료 기준
A2: LoanSight AI 완료 기준 v1.2
A4: 작업별 산출물·완료 조건·근거와 관련 요구(R)·기능(F)·미정 질문(U)을 ID로 연결합니다.
A5: 기준 문서: C:/Users/kdh80/Desktop/KB-Bridge/최종 Project/03 실적변동원인분석서비스/기획안_재무나침반_v1.0.docx
A6: 주담당은 작업 관리에서 확인합니다. 기존 노션의 팀 메모는 보존하며 Markdown 상세에도 포함합니다.
A8: ID | B8: 작업 | C8: 협업 | D8: 선행 ID | E8: 산출물 | F8: 완료 기준 | G8: 완료근거 | H8: 관련 요구사항 | I8: 관련 기능 | J8: 미정 질문
A9: 1.1 | B9: =INDEX('작업 관리'!$C$9:$C$77,MATCH($A9,'작업 관리'!$A$9:$A$77,0)) -> 기획안 v1.0 확정본 정리 | C9: 오준탁 | D9: 없음 | E9: LoanSight AI 기획안 v1.0 | F9: 재무·주석 결합 부도 예측, 역할·일정·검증·필수 기능을 반영한 v1.0 문서 확인。기존 v1.0 완료 기록이며 이번 v2.0 반영 완료를 뜻하지 않는다. | G9: 기획안_LoanSight AI_v1.0.docx
A10: 1.2 | B10: =INDEX('작업 관리'!$C$9:$C$77,MATCH($A10,'작업 관리'!$A$9:$A$77,0)) -> 기획 발표자료 v0.2 초안 보존 | C10: 최수인 | D10: 1.1 | E10: 11장 기획 발표자료 | F10: 기존 11장·발표자 노트 초안 확인. v1.0 반영은 1.8에서 별도 수행。기존 초안 보존 완료이며 최신 발표자료는 별도 검토한다. | G10: KB-Bridge_LoanSight AI_기획발표_v0.2.0.pptx
A11: 1.3 | B11: =INDEX('작업 관리'!$C$9:$C$77,MATCH($A11,'작업 관리'!$A$9:$A$77,0)) -> 범위와 역할 분담 합의 | C11: 전원 | D11: 1.1 | E11: 범위·담당 확정 기록 | F11: 4개 업종·상환/연체 위험 사건 예측·주석/위험 패널 필수 범위와 5명 역할을 확인한다. 세부 배정·공수·백업·날짜의 최종 팀 합의를 기록한다. | G11: KB-Bridge_재무나침반_기획발표_v0.2.0.pptx | H11: N-R01 N-R16 N-R30 | J11: N-U08 N-U09
A12: 1.4 | B12: =INDEX('작업 관리'!$C$9:$C$77,MATCH($A12,'작업 관리'!$A$9:$A$77,0)) -> 확정 4개 업종과 수집 범위 점검 | C12: 김동혁 | D12: 1.1 | E12: 업종 매핑·대상 제외·수집 범위표 | F12: 제조·건설·도소매·부동산 임대 4개를 DART 코드로 매핑하고 금융/보험·지주·스팩·운수/창고·장비/물품 렌탈·부동산 관리/중개를 제외한다. 세부분류·겸업 기준과 기간은 미정으로 표시한다. | G12: 기획안_LoanSight_AI_v2.0.docx | H12: N-R01 N-R32 | I12: N-F01 N-F30 | J12: N-U02 N-U15
A13: 1.6 | B13: =INDEX('작업 관리'!$C$9:$C$77,MATCH($A13,'작업 관리'!$A$9:$A$77,0)) -> 재무비율·계정·업종 계산 기준 정의 | C13: 김동민 | D13: 1.1 | E13: 비율 산식·계정·예외·근거 사전 | F13: 차입금·EBITDA·이자비용·현금흐름·회전율/회전일수의 산식과 출처를 정리한다. 평균/기말 잔액·금융원가 근사·임대보증금 포함 여부는 미정으로 남기고 0/음수/결측 처리 기준을 구분한다. | G13: 업종별_핵심재무지표_상환연체위험징후지표.docx | H13: N-R05 N-R07 N-R09 N-R33 N-R34 N-R35 | I13: N-F31 N-F32 N-F33 | J13: N-U11 N-U13 N-U14
A14: 1.7 | B14: =INDEX('작업 관리'!$C$9:$C$77,MATCH($A14,'작업 관리'!$A$9:$A$77,0)) -> 상환·연체 위험 사건과 12개월 라벨 정의 | C14: 김동민 | D14: 1.1 | E14: 복합 위험 사건·기준일·추적 기간 명세 | F14: 원리금 실제 연체/기한이익상실·지급거절·회생/채권은행 관리절차 신청·감사의견 변형/계속기업 불확실성을 유형별 기록한다. 상환과 무관한 관리종목/상장폐지는 제외한다. 유형별 심각도·사건/특징 역할·시점·비발생 판정은 원문 근거와 함께 합의한다. | G14: 기획안_LoanSight_AI_v2.1.docx | H14: N-R16 N-R17 N-R18 N-R20 | I14: N-F13 N-F14 N-F16 | J14: N-U01 N-U03
A15: 1.8 | B15: =INDEX('작업 관리'!$C$9:$C$77,MATCH($A15,'작업 관리'!$A$9:$A$77,0)) -> 기획 발표자료에 최신 범위 반영 | C15: 최수인 | D15: 1.1 | E15: 기획안 v2.0 기준 발표 개정 초안 | F15: 상환/연체 위험 사건 목표·4개 업종·렌탈 제외·주석 추출·위험 패널·논의 중인 15/5 표본을 반영한다. 기존 1.2 완료 기록과 구분하며 최종 발표는 6.2에서 정리한다. | H15: N-R01 N-R16 N-R38 N-R39 N-R40 N-R41 N-R42 N-R43 | J15: N-U02 N-U09
A16: 1.5 | B16: =INDEX('작업 관리'!$C$9:$C$77,MATCH($A16,'작업 관리'!$A$9:$A$77,0)) -> 기능 검증·원문 정답지 표본 선정 | C16: 김동민 | D16: 1.4 | E16: 기능/정답지 표본 선정안·확정 기록 | F16: 기능 검증 15곳·정답지 5곳은 논의 필요 값으로 두고 실제 기업·기간·규모를 합의한다. 기획안 인용 추출 표본 40개사, 계정 확보 표본, 모델 학습/평가 표본과 구분한다. | G16: KB-Bridge_업종별시총상위10_20261022_v0.0.2.xlsx | H16: N-R28 N-R37 N-R42 | I16: N-F25 N-F35 | J16: N-U02 N-U09 N-U19
A17: 1.M1 | B17: =INDEX('작업 관리'!$C$9:$C$77,MATCH($A17,'작업 관리'!$A$9:$A$77,0)) -> 업종·데이터·모델 설계 기준 확정 | C17: 전원 | D17: 1.3, 1.5, 1.6, 1.7 | E17: 1차 범위 결정 기록 | F17: 4개 업종 매핑·기간·검증/학습 표본·산식·위험 사건/관측 창의 결정 여부를 기록한다. 미정 질문의 미해결은 완료 처리하지 않으며, 최신 v2.0/v0.0.4 변경은 1.9에서 재확인한다. | G17: KB-Bridge_재무나침반_기획발표_v0.2.0.pptx | H17: N-R01 N-R16 N-R17 N-R18 N-R28 N-R32 N-R33 | J17: N-U01 N-U02 N-U03 N-U09
A18: 1.9 | B18: =INDEX('작업 관리'!$C$9:$C$77,MATCH($A18,'작업 관리'!$A$9:$A$77,0)) -> v2.0·v0.0.4 변경 및 미정 의사결정 정리 | C18: 전원 | D18: 1.1 | E18: 변경/충돌·미정 질문 20개·범위 기록 | F18: 요구사항의 10/23 팀 결정(4개 업종·렌탈 제외·15/5 논의 필요)을 충돌 부분에 우선한다. R01~43/F01~41 연결과 20개 질문의 담당·결정 필요 시점을 기록한다. R31/F28~29는 확장 검토 기록만 남기며 초기 개발 완료로 세지 않는다. | H18: N-R01 N-R16 N-R28 N-R30 N-R31 | I18: N-F27 N-F28 N-F29 | J18: N-U01 N-U02 N-U03 N-U04 N-U05 N-U06 N-U07 N-U08 N-U09 N-U10 N-U11 N-U12 N-U13 N-U14 N-U15 N-U16 N-U17 N-U18 N-U19 N-U20
A19: 1.10 | B19: =INDEX('작업 관리'!$C$9:$C$77,MATCH($A19,'작업 관리'!$A$9:$A$77,0)) -> 6개 판단 축·업종 지표·단계 가설 검토 | C19: 김동민·최수인 | D19: 1.9 | E19: 6축 지표·경고/주의/관찰 초안·근거/미정표 | F19: 상환재원·유동성/만기·구조·우발/부외·외부평가·담보/회수 6축과 업종 우선 지표를 연결한다. 1배/3년/2년 등의 수치는 팀 가설로 표시하고 현직자 검토와 기준 버전·누락 처리·종합 우선순위는 미정 상태를 구분한다. | H19: N-R14 N-R24 N-R36 N-R38 N-R39 | I19: N-F21 N-F34 N-F36 N-F37 | J19: N-U06 N-U12 N-U17
A20: 2.7 | B20: =INDEX('작업 관리'!$C$9:$C$77,MATCH($A20,'작업 관리'!$A$9:$A$77,0)) -> 위험 사건 이력 수집과 원문 대조 | C20: 최수인 | D20: 1.7 | E20: 위험 사건별 이력·사건일·공시 원문 | F20: 주요사항보고서·감사보고서·기한이익상실 공시를 대조하고 유형·사건일·최초 공개일·접수번호를 보존한다. API 미조회만으로 비발생을 단정하지 않고 제공 기간·기업 범위·누락/실패를 기록한다. | H20: N-R17 N-R18 N-R20 | I20: N-F13 N-F14 N-F16 | J20: N-U01 N-U03
A21: 2.1 | B21: =INDEX('작업 관리'!$C$9:$C$77,MATCH($A21,'작업 관리'!$A$9:$A$77,0)) -> 재무·공시 수집과 출처 저장 | C21: 서종원 | D21: 1.M1 | E21: 수집 응답·공시 목록·캐시 | F21: 기업·업종·보고서·접수번호·공시일·수집일·원본·버전·정정 관계를 보존한다. 공개 당시 알 수 있는 데이터만 모델 시점에 연결하고 실패/캐시 정책은 별도 기록한다. | H21: N-R03 N-R27 N-R30 | I21: N-F02 N-F24 N-F27 | J21: N-U08
A22: 2.2 | B22: =INDEX('작업 관리'!$C$9:$C$77,MATCH($A22,'작업 관리'!$A$9:$A$77,0)) -> 계정 매핑과 비교 기준 정렬 | C22: 오준탁 | D22: 1.M1 | E22: 계정 매핑·표준 데이터 | F22: 연결/별도·통화·단위·기간·정정 기준과 표준 계정 매핑을 구분한다. 미확보/공시 없음/계산 불가/0을 합치지 않고 결측 원인을 보존한다. | H22: N-R04 N-R05 N-R33 N-R37 | I22: N-F03 N-F31 N-F35 | J22: N-U11 N-U13 N-U14
A23: 2.8 | B23: =INDEX('작업 관리'!$C$9:$C$77,MATCH($A23,'작업 관리'!$A$9:$A$77,0)) -> 과거 재무·주석 학습자료 수집 | C23: 김동민 | D23: 1.M1 | E23: 기업·공시시점별 학습 원자료 | F23: 기업·공시시점별 재무와 원문 주석을 수집하고 원본 버전·회계 범위·공개일을 저장한다. 기능 검증 수와 모델 학습/평가 기업·관측치·위험 사건 수를 구분한다. | H23: N-R03 N-R18 N-R19 N-R20 | I23: N-F02 N-F14 N-F15 N-F16 | J23: N-U01 N-U03 N-U04
A24: 2.5 | B24: =INDEX('작업 관리'!$C$9:$C$77,MATCH($A24,'작업 관리'!$A$9:$A$77,0)) -> 원문 대조 정답지 작성 | C24: 오준탁·김동민 | D24: 1.5, 1.6 | E24: 수치·주석·출처 정답지 | F24: 선정 표본 수는 N-U02 합의 후 적용한다(5곳 논의 필요). 수치·산식·주석·검출 상태·원문·확인 항목을 대조하고 정답지 판정자·예외·미검출 원인을 기록한다. | H24: N-R28 N-R33 N-R34 N-R35 N-R37 N-R41 N-R42 N-R43 | I24: N-F25 N-F35 N-F39 N-F40 N-F41 | J24: N-U02 N-U09 N-U19
A25: 2.3 | B25: =INDEX('작업 관리'!$C$9:$C$77,MATCH($A25,'작업 관리'!$A$9:$A$77,0)) -> 주석 구간·교차참조·추출 표본 확보 | C25: 최수인 | D25: 2.1 | E25: 관련 주석 원문 표본 | F25: 소송·보증·담보/약정·차입 만기·PF·리스 등 공통/업종별 구간을 확보하고 표/본문·교차참조·중복과 출처 위치를 기록한다. 장비/물품 렌탈 추가 수집은 제외한다. | H25: N-R11 N-R41 N-R42 N-R43 | I25: N-F09 N-F39 N-F40 N-F41 | J25: N-U04 N-U18 N-U19
A26: 2.9 | B26: =INDEX('작업 관리'!$C$9:$C$77,MATCH($A26,'작업 관리'!$A$9:$A$77,0)) -> 12개월 라벨과 관측기간 구성 | C26: 최수인 | D26: 2.7, 2.8 | E26: 모델 학습·평가 표본 명세 | F26: 공개 기준일 다음 12개월 위험 사건과 비발생/추적 미완료를 구분한다. 충분한 추적 종료 전에 정상 라벨을 부여하지 않고 이미 사건 발생한 관측은 분리한다. 학습 결과가 다음 검증 시작 전에 확정되도록 설계한다. | H26: N-R16 N-R18 N-R20 | I26: N-F14 N-F16 | J26: N-U01 N-U03
A27: 2.10 | B27: =INDEX('작업 관리'!$C$9:$C$77,MATCH($A27,'작업 관리'!$A$9:$A$77,0)) -> 업종별 필수 계정 확보율 점검 | C27: 김동혁·최수인 | D27: 1.9, 2.2 | E27: 업종/항목 확보율·결측 사유표 | F27: 4개 업종의 필수 계정·이자비용·차입/만기·EBITDA·운전자본을 점검한다. 업종별 5개 이상은 계정 점검 계획이며 70%는 예시일 뿐 합격 확정값이 아니다. 확보 결과와 대안/추가 수집을 기록한다. | H27: N-R05 N-R33 N-R34 N-R35 N-R37 | I27: N-F03 N-F31 N-F32 N-F33 N-F35 | J27: N-U02 N-U11 N-U13 N-U14
A28: 2.11 | B28: =INDEX('작업 관리'!$C$9:$C$77,MATCH($A28,'작업 관리'!$A$9:$A$77,0)) -> 주석 원문 구간·추출 검출 상태 저장 | C28: 김동민·최수인 | D28: 1.9, 2.1 | E28: 원문 구간·교차참조·구조화/검출 상태 저장 구조 | F28: 보고서/구간·접수번호·공개일·버전·현재/전기·방향·한도/잔액·검수·검출/공시상 없음/미검출/추출 실패를 분리한다. 공시상 없음은 명시 원문이 있어야 하며 금액 미기재/실패를 0으로 바꾸지 않는다. | H28: N-R03 N-R12 N-R27 N-R41 N-R42 N-R43 | I28: N-F02 N-F10 N-F24 N-F39 N-F40 N-F41 | J28: N-U04 N-U08 N-U18
A29: 2.4 | B29: =INDEX('작업 관리'!$C$9:$C$77,MATCH($A29,'작업 관리'!$A$9:$A$77,0)) -> 데이터 정합성과 결측 점검 | C29: 김동혁 | D29: 2.1, 2.2 | E29: 품질 점검 결과 | F29: 합계·부호·단위·계정 매핑·결측/0·원문 일치를 검산한다. 계정 확보율을 업종별로 기록하고 예시 합격률을 확정 기준으로 쓰지 않는다. | H29: N-R05 N-R28 N-R37 | I29: N-F03 N-F25 N-F35 | J29: N-U09
... A31: 3.2 | B31: =INDEX('작업 관리'!$C$9:$C$77,MATCH($A31,'작업 관리'!$A$9:$A$77,0)) -> 기업 검색과 업종 표시·필터 | C31: 김동혁 | D31: 1.M1 | E31: 검색·업종 선택 화면 | F31: 기업 식별·DART 업종코드·서비스 업종·세부분류·적용 기준·보고 기간·연결/별도·결산월을 표시한다. 수동 업종 변경과 근거는 3.12에 연결한다. | H31: N-R01 N-R02 N-R32 | I31: N-F01 N-F30 | J31: N-U02 N-U15
A32: 3.1 | B32: =INDEX('작업 관리'!$C$9:$C$77,MATCH($A32,'작업 관리'!$A$9:$A$77,0)) -> 변동 기여도와 재무비율 계산 | C32: 서종원 | D32: 1.M1 | E32: 계산 로직·검산 결과 | F32: 영업이익 변동 금액·기여도·잔차와 0/음수 분모·적자 전환·결측을 검산한다. 숫자 분해를 인과관계로 단정하지 않는다. | H32: N-R08 N-R09 | I32: N-F06 N-F07
A33: 3.12 | B33: =INDEX('작업 관리'!$C$9:$C$77,MATCH($A33,'작업 관리'!$A$9:$A$77,0)) -> 겸업 판정·업종 변경 근거 기록 | C33: 오준탁·김동민 | D33: 1.9, 3.2 | E33: DART 매핑·복합 판정·수동 변경 기록 | F33: 기업/업종/세부분류와 건설/부동산 임대 적용 기준을 표시한다. 복합 판정 매출 비중·권한/저장은 N-U15 합의 후 적용하고 담당자 변경 사유·근거를 보존해 변경 업종 기준으로 다시 분석한다. | H33: N-R01 N-R02 N-R32 | I33: N-F01 N-F30 | J33: N-U02 N-U15
A34: 3.3 | B34: =INDEX('작업 관리'!$C$9:$C$77,MATCH($A34,'작업 관리'!$A$9:$A$77,0)) -> 핵심 재무 대시보드와 차트 | C34: 김동민 | D34: 3.2, 1.6 | E34: 영업이익·변동·현금흐름 화면 | F34: 영업이익 우선 배치·업종별 감가상각 강조·차입/상환능력·운전자본·기간/회계 범위/원문을 표시한다. 신규 업종 패널은 기존 N-S04에 붙이고 화면을 별도 신설하지 않는다. | H34: N-R07 N-R09 N-R27 N-R33 N-R34 N-R35 N-R38 N-R40 | I34: N-F05 N-F07 N-F24 N-F32 N-F33 N-F36 N-F38 | J34: N-U20
A35: 3.8 | B35: =INDEX('작업 관리'!$C$9:$C$77,MATCH($A35,'작업 관리'!$A$9:$A$77,0)) -> 차입 상환능력·영업순환 지표 계산 | C35: 서종원·오준탁 | D35: 1.6, 2.4, 2.10 | E35: 차입/상환·CCC·운전자본 계산·검산 기록 | F35: 차입금/EBITDA/이자보상과 업종별 회전율·일수·현금전환주기를 산출한다. 금융원가 근사·임대보증금·평균 잔액·분모 예외는 결정 기준/미정에 맞춰 표시하며 정답지로 검산한다. | H35: N-R07 N-R09 N-R33 N-R34 N-R35 N-R37 | I35: N-F05 N-F07 N-F31 N-F32 N-F33 N-F35 | J35: N-U11 N-U13 N-U14
A36: 3.4 | B36: =INDEX('작업 관리'!$C$9:$C$77,MATCH($A36,'작업 관리'!$A$9:$A$77,0)) -> 확인 체크와 재무 검토 기록 초안 | C36: 오준탁 | D36: 3.3 | E36: 확인 기록·메모 초안 | F36: 규칙 징후 단계·모델 확률·담당자 확인 상태를 별도로 저장/표시한다. 미확인 모음과 근거/수치 복사·수정 및 내부 추가 확인 안내를 제공한다. | H36: N-R14 N-R24 N-R25 N-R26 N-R27 N-R39 N-R43 | I36: N-F21 N-F22 N-F23 N-F24 N-F37 N-F41 | J36: N-U08 N-U17
A37: 3.6 | B37: =INDEX('작업 관리'!$C$9:$C$77,MATCH($A37,'작업 관리'!$A$9:$A$77,0)) -> 업종별 확인 기준 검토 | C37: 최수인 | D37: 2.4, 2.5 | E37: 업종별 점검 기준 | F37: 업종별 점검표·6개 판단 축과 근거를 연결하고 팀 가설 수치와 검증 기준을 구분한다. 규칙 단계가 은행 건전성 분류/내부 등급/승인 결정을 대신하지 않도록 안내한다. | H37: N-R14 N-R24 N-R36 N-R38 N-R39 | I37: N-F21 N-F34 N-F36 N-F37 | J37: N-U06 N-U12 N-U17
A38: 3.9 | B38: =INDEX('작업 관리'!$C$9:$C$77,MATCH($A38,'작업 관리'!$A$9:$A$77,0)) -> 업종 위험 지표·징후 단계 판정 연결 | C38: 오준탁·서종원 | D38: 1.10, 3.8 | E38: 업종별 지표·규칙 버전·단계/판정 근거 | F38: 6축·우선 지표와 경고/주의/관찰 조건을 연결한다. 가설 수치·기준 버전·근거·계산 불가를 표시하고 미확보를 관찰/정상으로 치환하지 않는다. 경고는 상단 고정/원문 확인 필수, 주의는 확인 항목에 추가한다. 규칙 단계·미래 모델 확률·담당자 체크는 독립 상태로 유지한다. | H38: N-R14 N-R24 N-R36 N-R38 N-R39 | I38: N-F21 N-F34 N-F36 N-F37 | J38: N-U06 N-U12 N-U17
A39: 3.11 | B39: =INDEX('작업 관리'!$C$9:$C$77,MATCH($A39,'작업 관리'!$A$9:$A$77,0)) -> 직접 입력·출처·재계산 경로 검증 | C39: 김동민·최수인 | D39: 2.4, 3.3 | E39: 수기 입력·출처/시점 표시·검증 결과 | F39: 직접 입력의 원문/입력자/시점과 공시 수집 값을 구분하고 필수 입력·단위·누락/0·재계산을 검증한다. 내부 은행 자료를 수집하거나 임의 입력을 공식 원문으로 표시하지 않는다. | H39: N-R06 N-R27 | I39: N-F04 N-F24 | J39: N-U08
A40: 3.10 | B40: =INDEX('작업 관리'!$C$9:$C$77,MATCH($A40,'작업 관리'!$A$9:$A$77,0)) -> 기존 주석 화면에 업종 위험 패널·차트 연결 | C40: 김동민·오준탁 | D40: 3.9, 2.11 | E40: N-S04 위험 패널·업종 차트·원문 연결 | F40: 기존 N-S04에 단계/5개년 추세/업종 내 위치/주석 근거를 배치한다. 제조 CCC·도소매 마진/매입채무/리스·건설 PF 만기·임대 차입만기/금리/EBITDA 커버/LTV 성격 비율을 업종 기준에 맞게 표시한다. 3개년 비교와 구분하고 표본 부족은 비교 보류, 결측은 자료 없음으로 표시한다. 색과 텍스트를 병기하고 게이지/레이더는 사용하지 않는다. 최소 표본과 차트 우선순위는 N-U20을 따른다. | H40: N-R11 N-R27 N-R38 N-R39 N-R40 N-R43 | I40: N-F24 N-F36 N-F37 N-F38 N-F41 | J40: N-U17 N-U20
A41: 3.5 | B41: =INDEX('작업 관리'!$C$9:$C$77,MATCH($A41,'작업 관리'!$A$9:$A$77,0)) -> 현금흐름 괴리와 업종 비교 분석 | C41: 오준탁 | D41: 2.6, 3.1 | E41: 분석 결과와 적용 범위 | F41: 현금흐름과 이익 차이·차입/운전자본·기존 3개년 추세와 비교 분포·표본 한계를 설명한다. 패널 5개년 추세는 별도 시각화 기준으로 구분한다. | H41: N-R09 N-R10 N-R34 N-R35 N-R40 | I41: N-F07 N-F08 N-F32 N-F33 N-F38 | J41: N-U06 N-U16 N-U20
A42: 3.7 | B42: =INDEX('작업 관리'!$C$9:$C$77,MATCH($A42,'작업 관리'!$A$9:$A$77,0)) -> 핵심 분석과 확인 항목 통합 | C42: 김동민 | D42: 3.4, 3.6 | E42: 통합 대시보드 | F42: 계산·확인 항목·원문·메모 연결을 검증한다. 규칙 단계/미래 확률/담당자 체크를 혼동하지 않고 패널 통합 검수는 3.M2와 5.7에 연결한다. | H42: N-R07 N-R14 N-R24 N-R25 N-R26 N-R27 N-R40 | I42: N-F05 N-F21 N-F22 N-F23 N-F24 N-F38
A43: 3.M2 | B43: =INDEX('작업 관리'!$C$9:$C$77,MATCH($A43,'작업 관리'!$A$9:$A$77,0)) -> 핵심 재무 기능 통합 완료 판단 | C43: 서종원·김동민 | D43: 3.5, 3.7, 2.4, 3.10, 3.11, 3.12 | E43: 핵심 기능 확인 기록 | F43: 정량 분석·직접 입력·업종 변경 기록·업종별 패널과 차트의 검수 대상 버전을 고정한다. 수치 가설·미정 표본·검증 전 결과를 실제 성과로 표시하지 않는다. | H43: N-R06 N-R07 N-R28 N-R32 N-R38 N-R39 N-R40 | I43: N-F04 N-F05 N-F25 N-F30 N-F36 N-F37 N-F38
A44: 4.1 | B44: =INDEX('작업 관리'!$C$9:$C$77,MATCH($A44,'작업 관리'!$A$9:$A$77,0)) -> 주석 요약 형식과 확인 안내 정의 | C44: 김동혁 | D44: 2.3, 2.5 | E44: 추출 필드·요약 형식 | F44: 공통 6범주/업종 추가 사전과 유형·방향·금액·통화·상태·기준일·원문 위치·검출 상태·검수 기록을 정의한다. 표/본문 중복·현재/전기·한도/잔액을 구분하고 코드는 N-U04/N-U18 합의 후 고정한다. | H44: N-R11 N-R12 N-R13 N-R14 N-R41 N-R42 N-R43 | I44: N-F09 N-F10 N-F11 N-F39 N-F40 N-F41 | J44: N-U04 N-U07 N-U18
...
