Workbook

Sheet 한눈에 보기
A2: LoanSight AI WBS v1.4
A4: 버전 | B4: 변경 내용 | C4: 개정일 | D4: 원저자/개정자 | E4: 검토·승인 | F4: 상태
A5: v1.1 | B5: 이전 기준 반영. 원문 보존. | C5: 46319 | D5: 김동혁 | E5: 미정 | F5: 이전본
A6: v1.2 | B6: 상태·근거 갱신. 누락된 개정 이력 보정. | C6: 46322 | D6: 최수인 | E6: 미정 | F6: 이전본
A7: v1.4 | B7: v2.3 통합 기획 반영·징후 기준 명확화·v2.1 확장 축소·CFS 우선/OFS 전환. 화면설계서 보존. | C7: 46324 | D7: 미정 | E7: 미정 | F7: 검토 대기
A8: 전체 항목 | B8: =COUNTA('작업 관리'!A9:A61) -> 53 | C8: 완료 확인 | D8: =COUNTIF('작업 관리'!J9:J61,"완료 확인") -> 0 | E8: 진행 미확인 | F8: =COUNTIF('작업 관리'!G9:G61,"미확인") -> 0 | G8: 예정 | H8: =COUNTIF('작업 관리'!G9:G61,"예정") -> 36
A10: 단계별 계획
A11: 단계 | B11: 핵심 산출물 | C11: 필수 | D11: 보완 | E11: 마일스톤 | F11: 완료 확인 | G11: 시작 | H11: 마감
A12: 기획·범위 | B12: 현행 서비스 작업 | C12: =COUNTIFS('작업 관리'!$B$9:$B$61,$A12,'작업 관리'!$I$9:$I$61,"필수") -> 7 | D12: =COUNTIFS('작업 관리'!$B$9:$B$61,$A12,'작업 관리'!$I$9:$I$61,"보완") -> 0 | E12: =COUNTIFS('작업 관리'!$B$9:$B$61,$A12,'작업 관리'!$I$9:$I$61,"마일스톤") -> 1 | F12: =COUNTIFS('작업 관리'!$B$9:$B$61,$A12,'작업 관리'!$J$9:$J$61,"완료 확인") -> 0 | G12: =IFERROR(_xlfn.AGGREGATE(15,6,'작업 관리'!$E$9:$E$61/('작업 관리'!$B$9:$B$61=$A12),1),"") -> 46317 | H12: =IFERROR(_xlfn.AGGREGATE(14,6,'작업 관리'!$F$9:$F$61/('작업 관리'!$B$9:$B$61=$A12),1),"") -> 46321
A13: 데이터 | B13: 현행 서비스 작업 | C13: =COUNTIFS('작업 관리'!$B$9:$B$61,$A13,'작업 관리'!$I$9:$I$61,"필수") -> 9 | D13: =COUNTIFS('작업 관리'!$B$9:$B$61,$A13,'작업 관리'!$I$9:$I$61,"보완") -> 0 | E13: =COUNTIFS('작업 관리'!$B$9:$B$61,$A13,'작업 관리'!$I$9:$I$61,"마일스톤") -> 0 | F13: =COUNTIFS('작업 관리'!$B$9:$B$61,$A13,'작업 관리'!$J$9:$J$61,"완료 확인") -> 0 | G13: =IFERROR(_xlfn.AGGREGATE(15,6,'작업 관리'!$E$9:$E$61/('작업 관리'!$B$9:$B$61=$A13),1),"") -> 46318 | H13: =IFERROR(_xlfn.AGGREGATE(14,6,'작업 관리'!$F$9:$F$61/('작업 관리'!$B$9:$B$61=$A13),1),"") -> 46323
A14: 분석·화면 | B14: 현행 서비스 작업 | C14: =COUNTIFS('작업 관리'!$B$9:$B$61,$A14,'작업 관리'!$I$9:$I$61,"필수") -> 12 | D14: =COUNTIFS('작업 관리'!$B$9:$B$61,$A14,'작업 관리'!$I$9:$I$61,"보완") -> 0 | E14: =COUNTIFS('작업 관리'!$B$9:$B$61,$A14,'작업 관리'!$I$9:$I$61,"마일스톤") -> 1 | F14: =COUNTIFS('작업 관리'!$B$9:$B$61,$A14,'작업 관리'!$J$9:$J$61,"완료 확인") -> 0 | G14: =IFERROR(_xlfn.AGGREGATE(15,6,'작업 관리'!$E$9:$E$61/('작업 관리'!$B$9:$B$61=$A14),1),"") -> 46319 | H14: =IFERROR(_xlfn.AGGREGATE(14,6,'작업 관리'!$F$9:$F$61/('작업 관리'!$B$9:$B$61=$A14),1),"") -> 46325
A15: AI·뉴스 | B15: 현행 서비스 작업 | C15: =COUNTIFS('작업 관리'!$B$9:$B$61,$A15,'작업 관리'!$I$9:$I$61,"필수") -> 5 | D15: =COUNTIFS('작업 관리'!$B$9:$B$61,$A15,'작업 관리'!$I$9:$I$61,"보완") -> 2 | E15: =COUNTIFS('작업 관리'!$B$9:$B$61,$A15,'작업 관리'!$I$9:$I$61,"마일스톤") -> 1 | F15: =COUNTIFS('작업 관리'!$B$9:$B$61,$A15,'작업 관리'!$J$9:$J$61,"완료 확인") -> 0 | G15: =IFERROR(_xlfn.AGGREGATE(15,6,'작업 관리'!$E$9:$E$61/('작업 관리'!$B$9:$B$61=$A15),1),"") -> 46321 | H15: =IFERROR(_xlfn.AGGREGATE(14,6,'작업 관리'!$F$9:$F$61/('작업 관리'!$B$9:$B$61=$A15),1),"") -> 46325
A16: 위험 사건 예측 | B16: 현행 서비스 작업 | C16: =COUNTIFS('작업 관리'!$B$9:$B$61,$A16,'작업 관리'!$I$9:$I$61,"필수") -> 4 | D16: =COUNTIFS('작업 관리'!$B$9:$B$61,$A16,'작업 관리'!$I$9:$I$61,"보완") -> 0 | E16: =COUNTIFS('작업 관리'!$B$9:$B$61,$A16,'작업 관리'!$I$9:$I$61,"마일스톤") -> 1 | F16: =COUNTIFS('작업 관리'!$B$9:$B$61,$A16,'작업 관리'!$J$9:$J$61,"완료 확인") -> 0 | G16: =IFERROR(_xlfn.AGGREGATE(15,6,'작업 관리'!$E$9:$E$61/('작업 관리'!$B$9:$B$61=$A16),1),"") -> 46323 | H16: =IFERROR(_xlfn.AGGREGATE(14,6,'작업 관리'!$F$9:$F$61/('작업 관리'!$B$9:$B$61=$A16),1),"") -> 46326
A17: 통합·운영 | B17: 현행 서비스 작업 | C17: =COUNTIFS('작업 관리'!$B$9:$B$61,$A17,'작업 관리'!$I$9:$I$61,"필수") -> 2 | D17: =COUNTIFS('작업 관리'!$B$9:$B$61,$A17,'작업 관리'!$I$9:$I$61,"보완") -> 0 | E17: =COUNTIFS('작업 관리'!$B$9:$B$61,$A17,'작업 관리'!$I$9:$I$61,"마일스톤") -> 1 | F17: =COUNTIFS('작업 관리'!$B$9:$B$61,$A17,'작업 관리'!$J$9:$J$61,"완료 확인") -> 0 | G17: =IFERROR(_xlfn.AGGREGATE(15,6,'작업 관리'!$E$9:$E$61/('작업 관리'!$B$9:$B$61=$A17),1),"") -> 46326 | H17: =IFERROR(_xlfn.AGGREGATE(14,6,'작업 관리'!$F$9:$F$61/('작업 관리'!$B$9:$B$61=$A17),1),"") -> 46328
A18: 제출·발표 | B18: 현행 서비스 작업 | C18: =COUNTIFS('작업 관리'!$B$9:$B$61,$A18,'작업 관리'!$I$9:$I$61,"필수") -> 5 | D18: =COUNTIFS('작업 관리'!$B$9:$B$61,$A18,'작업 관리'!$I$9:$I$61,"보완") -> 0 | E18: =COUNTIFS('작업 관리'!$B$9:$B$61,$A18,'작업 관리'!$I$9:$I$61,"마일스톤") -> 2 | F18: =COUNTIFS('작업 관리'!$B$9:$B$61,$A18,'작업 관리'!$J$9:$J$61,"완료 확인") -> 0 | G18: =IFERROR(_xlfn.AGGREGATE(15,6,'작업 관리'!$E$9:$E$61/('작업 관리'!$B$9:$B$61=$A18),1),"") -> 46329 | H18: =IFERROR(_xlfn.AGGREGATE(14,6,'작업 관리'!$F$9:$F$61/('작업 관리'!$B$9:$B$61=$A18),1),"") -> 46331
A21: 현재 문서 기준 | B21: 기획안 v2.3 / 요구사항 v0.0.7 / PRD·기능 v0.0.6. CFS 우선, 없으면 OFS.
A24: 팀 품질관리 문서 | B24: https://app.notion.com/p/40680be201ba81ddb717d75d409cde98

Sheet 작업 관리
A2: LoanSight AI 작업 관리 v1.4
A4: 상태·진행률은 실제 확인값만 입력합니다. 완료는 진행률 100%와 완료근거를 함께 기록합니다.
A5: 기획안 v2.3 / 요구사항 v0.0.7. 기존 담당·계획·진행·근거 보존.
A6: 같은 날의 선행·후속 작업은 당일 인수인계를 전제로 합니다. 마감일만으로 완료 처리하지 않습니다.
A8: ID | B8: 단계 | C8: 작업 | D8: 주담당 | E8: 시작 | F8: 마감 | G8: 상태 | H8: 진행률 | I8: 범위 | J8: 입력 확인
A9: 1.3 | B9: 기획·범위 | C9: 범위와 역할 분담 합의 | D9: 김동혁 | E9: 46317 | F9: 46317 | G9: 진행중 | I9: 필수 | J9: =IF(G9="완료",IF(AND(H9=1,LEN(INDEX('완료 기준'!$G$9:$G$61,MATCH(A9,'완료 기준'!$A$9:$A$61,0)))>0),"완료 확인","근거 확인 필요"),"")
A10: 1.4 | B10: 기획·범위 | C10: 확정 4개 업종과 수집 범위 점검 | D10: 김동민 | E10: 46317 | F10: 46318 | G10: 진행중 | I10: 필수 | J10: =IF(G10="완료",IF(AND(H10=1,LEN(INDEX('완료 기준'!$G$9:$G$61,MATCH(A10,'완료 기준'!$A$9:$A$61,0)))>0),"완료 확인","근거 확인 필요"),"")
A11: 1.6 | B11: 기획·범위 | C11: 재무비율·계정·업종 계산 기준 정의 | D11: 오준탁 | E11: 46317 | F11: 46318 | G11: 진행중 | I11: 필수 | J11: =IF(G11="완료",IF(AND(H11=1,LEN(INDEX('완료 기준'!$G$9:$G$61,MATCH(A11,'완료 기준'!$A$9:$A$61,0)))>0),"완료 확인","근거 확인 필요"),"")
A12: 1.7 | B12: 기획·범위 | C12: 상환·연체 위험 사건과 12개월 라벨 정의 | D12: 김동혁 | E12: 46317 | F12: 46318 | G12: 진행중 | I12: 필수 | J12: =IF(G12="완료",IF(AND(H12=1,LEN(INDEX('완료 기준'!$G$9:$G$61,MATCH(A12,'완료 기준'!$A$9:$A$61,0)))>0),"완료 확인","근거 확인 필요"),"")
A13: 1.8 | B13: 기획·범위 | C13: 기획 발표자료에 최신 범위 반영 | D13: 오준탁 | E13: 46317 | F13: 46318 | G13: 진행중 | I13: 필수 | J13: =IF(G13="완료",IF(AND(H13=1,LEN(INDEX('완료 기준'!$G$9:$G$61,MATCH(A13,'완료 기준'!$A$9:$A$61,0)))>0),"완료 확인","근거 확인 필요"),"")
A14: 1.M1 | B14: 기획·범위 | C14: 업종·데이터·모델 설계 기준 확정 | D14: 김동혁 | E14: 46318 | F14: 46318 | G14: 진행중 | I14: 마일스톤 | J14: =IF(G14="완료",IF(AND(H14=1,LEN(INDEX('완료 기준'!$G$9:$G$61,MATCH(A14,'완료 기준'!$A$9:$A$61,0)))>0),"완료 확인","근거 확인 필요"),"")
A15: 1.9 | B15: 기획·범위 | C15: v2.3 연계 범위와 미정 결정 정리 | D15: 김동혁 | E15: 46319 | F15: 46319 | G15: 진행중 | I15: 필수 | J15: =IF(G15="완료",IF(AND(H15=1,LEN(INDEX('완료 기준'!$G$9:$G$61,MATCH(A15,'완료 기준'!$A$9:$A$61,0)))>0),"완료 확인","근거 확인 필요"),"")
A16: 1.10 | B16: 기획·범위 | C16: 6개 판단 관점·업종 지표·징후 기준 정리 | D16: 오준탁 | E16: 46319 | F16: 46321 | G16: 예정 | I16: 필수 | J16: =IF(G16="완료",IF(AND(H16=1,LEN(INDEX('완료 기준'!$G$9:$G$61,MATCH(A16,'완료 기준'!$A$9:$A$61,0)))>0),"완료 확인","근거 확인 필요"),"")
A17: 2.7 | B17: 데이터 | C17: 위험 사건 이력 수집과 원문 대조 | D17: 김동혁 | E17: 46318 | F17: 46319 | G17: 예정 | I17: 필수 | J17: =IF(G17="완료",IF(AND(H17=1,LEN(INDEX('완료 기준'!$G$9:$G$61,MATCH(A17,'완료 기준'!$A$9:$A$61,0)))>0),"완료 확인","근거 확인 필요"),"")
A18: 2.1 | B18: 데이터 | C18: 재무·공시 수집과 출처 저장 | D18: 김동혁 | E18: 46319 | F18: 46320 | G18: 진행중 | I18: 필수 | J18: =IF(G18="완료",IF(AND(H18=1,LEN(INDEX('완료 기준'!$G$9:$G$61,MATCH(A18,'완료 기준'!$A$9:$A$61,0)))>0),"완료 확인","근거 확인 필요"),"")
A19: 2.2 | B19: 데이터 | C19: 계정 매핑과 비교 기준 정렬 | D19: 김동민 | E19: 46319 | F19: 46320 | G19: 진행중 | I19: 필수 | J19: =IF(G19="완료",IF(AND(H19=1,LEN(INDEX('완료 기준'!$G$9:$G$61,MATCH(A19,'완료 기준'!$A$9:$A$61,0)))>0),"완료 확인","근거 확인 필요"),"")
A20: 2.8 | B20: 데이터 | C20: 과거 재무·주석 학습자료 수집 | D20: 김동혁 | E20: 46319 | F20: 46320 | G20: 예정 | I20: 필수 | J20: =IF(G20="완료",IF(AND(H20=1,LEN(INDEX('완료 기준'!$G$9:$G$61,MATCH(A20,'완료 기준'!$A$9:$A$61,0)))>0),"완료 확인","근거 확인 필요"),"")
... A61: 6.M6 | B61: 제출·발표 | C61: 프로젝트 발표 | D61: 오준탁 | E61: 46331 | F61: 46331 | G61: 예정 | I61: 마일스톤 | J61: =IF(G61="완료",IF(AND(H61=1,LEN(INDEX('완료 기준'!$G$9:$G$61,MATCH(A61,'완료 기준'!$A$9:$A$61,0)))>0),"완료 확인","근거 확인 필요"),"")

Sheet 일정
A2: LoanSight AI 일정 v1.4
A4: 2026년 10월 21일~11월 5일 계획. 셀 색은 작업 관리의 시작·마감일을 따라 바뀝니다.
A5: 파랑은 작업 기간, 초록은 완료 작업, 보라는 마일스톤입니다. 옅은 회색 열은 주말입니다.
A6: 달력일 기준 계획입니다. 교육 일정과 팀 가용 시간을 확인한 뒤 세부 날짜를 확정합니다.
D7: 10월 | O7: 11월
A8: ID | B8: 작업 | C8: 담당 | D8: 46316 | E8: 46317 | F8: 46318 | G8: 46319 | H8: 46320 | I8: 46321 | J8: 46322 | K8: 46323 | L8: 46324 | M8: 46325 | N8: 46326 | O8: 46327 | P8: 46328 | Q8: 46329 | R8: 46330 | S8: 46331
A9: 1.3 | B9: 범위와 역할 분담 합의 | C9: 김동혁 | D9: =IF(AND(D$8>=INDEX('작업 관리'!$E$9:$E$61,MATCH($A9,'작업 관리'!$A$9:$A$61,0)),D$8<=INDEX('작업 관리'!$F$9:$F$61,MATCH($A9,'작업 관리'!$A$9:$A$61,0))),1,"") | E9: =IF(AND(E$8>=INDEX('작업 관리'!$E$9:$E$61,MATCH($A9,'작업 관리'!$A$9:$A$61,0)),E$8<=INDEX('작업 관리'!$F$9:$F$61,MATCH($A9,'작업 관리'!$A$9:$A$61,0))),1,"") -> 1 | F9: =IF(AND(F$8>=INDEX('작업 관리'!$E$9:$E$61,MATCH($A9,'작업 관리'!$A$9:$A$61,0)),F$8<=INDEX('작업 관리'!$F$9:$F$61,MATCH($A9,'작업 관리'!$A$9:$A$61,0))),1,"") | G9: =IF(AND(G$8>=INDEX('작업 관리'!$E$9:$E$61,MATCH($A9,'작업 관리'!$A$9:$A$61,0)),G$8<=INDEX('작업 관리'!$F$9:$F$61,MATCH($A9,'작업 관리'!$A$9:$A$61,0))),1,"") | H9: =IF(AND(H$8>=INDEX('작업 관리'!$E$9:$E$61,MATCH($A9,'작업 관리'!$A$9:$A$61,0)),H$8<=INDEX('작업 관리'!$F$9:$F$61,MATCH($A9,'작업 관리'!$A$9:$A$61,0))),1,"") | I9: =IF(AND(I$8>=INDEX('작업 관리'!$E$9:$E$61,MATCH($A9,'작업 관리'!$A$9:$A$61,0)),I$8<=INDEX('작업 관리'!$F$9:$F$61,MATCH($A9,'작업 관리'!$A$9:$A$61,0))),1,"") | J9: =IF(AND(J$8>=INDEX('작업 관리'!$E$9:$E$61,MATCH($A9,'작업 관리'!$A$9:$A$61,0)),J$8<=INDEX('작업 관리'!$F$9:$F$61,MATCH($A9,'작업 관리'!$A$9:$A$61,0))),1,"") | K9: =IF(AND(K$8>=INDEX('작업 관리'!$E$9:$E$61,MATCH($A9,'작업 관리'!$A$9:$A$61,0)),K$8<=INDEX('작업 관리'!$F$9:$F$61,MATCH($A9,'작업 관리'!$A$9:$A$61,0))),1,"") | ... S9: =IF(AND(S$8>=INDEX('작업 관리'!$E$9:$E$61,MATCH($A9,'작업 관리'!$A$9:$A$61,0)),S$8<=INDEX('작업 관리'!$F$9:$F$61,MATCH($A9,'작업 관리'!$A$9:$A$61,0))),1,"")
A10: 1.4 | B10: 확정 4개 업종과 수집 범위 점검 | C10: 김동민 | D10: =IF(AND(D$8>=INDEX('작업 관리'!$E$9:$E$61,MATCH($A10,'작업 관리'!$A$9:$A$61,0)),D$8<=INDEX('작업 관리'!$F$9:$F$61,MATCH($A10,'작업 관리'!$A$9:$A$61,0))),1,"") | E10: =IF(AND(E$8>=INDEX('작업 관리'!$E$9:$E$61,MATCH($A10,'작업 관리'!$A$9:$A$61,0)),E$8<=INDEX('작업 관리'!$F$9:$F$61,MATCH($A10,'작업 관리'!$A$9:$A$61,0))),1,"") -> 1 | F10: =IF(AND(F$8>=INDEX('작업 관리'!$E$9:$E$61,MATCH($A10,'작업 관리'!$A$9:$A$61,0)),F$8<=INDEX('작업 관리'!$F$9:$F$61,MATCH($A10,'작업 관리'!$A$9:$A$61,0))),1,"") -> 1 | G10: =IF(AND(G$8>=INDEX('작업 관리'!$E$9:$E$61,MATCH($A10,'작업 관리'!$A$9:$A$61,0)),G$8<=INDEX('작업 관리'!$F$9:$F$61,MATCH($A10,'작업 관리'!$A$9:$A$61,0))),1,"") | H10: =IF(AND(H$8>=INDEX('작업 관리'!$E$9:$E$61,MATCH($A10,'작업 관리'!$A$9:$A$61,0)),H$8<=INDEX('작업 관리'!$F$9:$F$61,MATCH($A10,'작업 관리'!$A$9:$A$61,0))),1,"") | I10: =IF(AND(I$8>=INDEX('작업 관리'!$E$9:$E$61,MATCH($A10,'작업 관리'!$A$9:$A$61,0)),I$8<=INDEX('작업 관리'!$F$9:$F$61,MATCH($A10,'작업 관리'!$A$9:$A$61,0))),1,"") | J10: =IF(AND(J$8>=INDEX('작업 관리'!$E$9:$E$61,MATCH($A10,'작업 관리'!$A$9:$A$61,0)),J$8<=INDEX('작업 관리'!$F$9:$F$61,MATCH($A10,'작업 관리'!$A$9:$A$61,0))),1,"") | K10: =IF(AND(K$8>=INDEX('작업 관리'!$E$9:$E$61,MATCH($A10,'작업 관리'!$A$9:$A$61,0)),K$8<=INDEX('작업 관리'!$F$9:$F$61,MATCH($A10,'작업 관리'!$A$9:$A$61,0))),1,"") | ... S10: =IF(AND(S$8>=INDEX('작업 관리'!$E$9:$E$61,MATCH($A10,'작업 관리'!$A$9:$A$61,0)),S$8<=INDEX('작업 관리'!$F$9:$F$61,MATCH($A10,'작업 관리'!$A$9:$A$61,0))),1,"")
A11: 1.6 | B11: 재무비율·계정·업종 계산 기준 정의 | C11: 오준탁 | D11: =IF(AND(D$8>=INDEX('작업 관리'!$E$9:$E$61,MATCH($A11,'작업 관리'!$A$9:$A$61,0)),D$8<=INDEX('작업 관리'!$F$9:$F$61,MATCH($A11,'작업 관리'!$A$9:$A$61,0))),1,"") | E11: =IF(AND(E$8>=INDEX('작업 관리'!$E$9:$E$61,MATCH($A11,'작업 관리'!$A$9:$A$61,0)),E$8<=INDEX('작업 관리'!$F$9:$F$61,MATCH($A11,'작업 관리'!$A$9:$A$61,0))),1,"") -> 1 | F11: =IF(AND(F$8>=INDEX('작업 관리'!$E$9:$E$61,MATCH($A11,'작업 관리'!$A$9:$A$61,0)),F$8<=INDEX('작업 관리'!$F$9:$F$61,MATCH($A11,'작업 관리'!$A$9:$A$61,0))),1,"") -> 1 | G11: =IF(AND(G$8>=INDEX('작업 관리'!$E$9:$E$61,MATCH($A11,'작업 관리'!$A$9:$A$61,0)),G$8<=INDEX('작업 관리'!$F$9:$F$61,MATCH($A11,'작업 관리'!$A$9:$A$61,0))),1,"") | H11: =IF(AND(H$8>=INDEX('작업 관리'!$E$9:$E$61,MATCH($A11,'작업 관리'!$A$9:$A$61,0)),H$8<=INDEX('작업 관리'!$F$9:$F$61,MATCH($A11,'작업 관리'!$A$9:$A$61,0))),1,"") | I11: =IF(AND(I$8>=INDEX('작업 관리'!$E$9:$E$61,MATCH($A11,'작업 관리'!$A$9:$A$61,0)),I$8<=INDEX('작업 관리'!$F$9:$F$61,MATCH($A11,'작업 관리'!$A$9:$A$61,0))),1,"") | J11: =IF(AND(J$8>=INDEX('작업 관리'!$E$9:$E$61,MATCH($A11,'작업 관리'!$A$9:$A$61,0)),J$8<=INDEX('작업 관리'!$F$9:$F$61,MATCH($A11,'작업 관리'!$A$9:$A$61,0))),1,"") | K11: =IF(AND(K$8>=INDEX('작업 관리'!$E$9:$E$61,MATCH($A11,'작업 관리'!$A$9:$A$61,0)),K$8<=INDEX('작업 관리'!$F$9:$F$61,MATCH($A11,'작업 관리'!$A$9:$A$61,0))),1,"") | ... S11: =IF(AND(S$8>=INDEX('작업 관리'!$E$9:$E$61,MATCH($A11,'작업 관리'!$A$9:$A$61,0)),S$8<=INDEX('작업 관리'!$F$9:$F$61,MATCH($A11,'작업 관리'!$A$9:$A$61,0))),1,"")
A12: 1.7 | B12: 상환·연체 위험 사건과 12개월 라벨 정의 | C12: 김동혁 | D12: =IF(AND(D$8>=INDEX('작업 관리'!$E$9:$E$61,MATCH($A12,'작업 관리'!$A$9:$A$61,0)),D$8<=INDEX('작업 관리'!$F$9:$F$61,MATCH($A12,'작업 관리'!$A$9:$A$61,0))),1,"") | E12: =IF(AND(E$8>=INDEX('작업 관리'!$E$9:$E$61,MATCH($A12,'작업 관리'!$A$9:$A$61,0)),E$8<=INDEX('작업 관리'!$F$9:$F$61,MATCH($A12,'작업 관리'!$A$9:$A$61,0))),1,"") -> 1 | F12: =IF(AND(F$8>=INDEX('작업 관리'!$E$9:$E$61,MATCH($A12,'작업 관리'!$A$9:$A$61,0)),F$8<=INDEX('작업 관리'!$F$9:$F$61,MATCH($A12,'작업 관리'!$A$9:$A$61,0))),1,"") -> 1 | G12: =IF(AND(G$8>=INDEX('작업 관리'!$E$9:$E$61,MATCH($A12,'작업 관리'!$A$9:$A$61,0)),G$8<=INDEX('작업 관리'!$F$9:$F$61,MATCH($A12,'작업 관리'!$A$9:$A$61,0))),1,"") | H12: =IF(AND(H$8>=INDEX('작업 관리'!$E$9:$E$61,MATCH($A12,'작업 관리'!$A$9:$A$61,0)),H$8<=INDEX('작업 관리'!$F$9:$F$61,MATCH($A12,'작업 관리'!$A$9:$A$61,0))),1,"") | I12: =IF(AND(I$8>=INDEX('작업 관리'!$E$9:$E$61,MATCH($A12,'작업 관리'!$A$9:$A$61,0)),I$8<=INDEX('작업 관리'!$F$9:$F$61,MATCH($A12,'작업 관리'!$A$9:$A$61,0))),1,"") | J12: =IF(AND(J$8>=INDEX('작업 관리'!$E$9:$E$61,MATCH($A12,'작업 관리'!$A$9:$A$61,0)),J$8<=INDEX('작업 관리'!$F$9:$F$61,MATCH($A12,'작업 관리'!$A$9:$A$61,0))),1,"") | K12: =IF(AND(K$8>=INDEX('작업 관리'!$E$9:$E$61,MATCH($A12,'작업 관리'!$A$9:$A$61,0)),K$8<=INDEX('작업 관리'!$F$9:$F$61,MATCH($A12,'작업 관리'!$A$9:$A$61,0))),1,"") | ... S12: =IF(AND(S$8>=INDEX('작업 관리'!$E$9:$E$61,MATCH($A12,'작업 관리'!$A$9:$A$61,0)),S$8<=INDEX('작업 관리'!$F$9:$F$61,MATCH($A12,'작업 관리'!$A$9:$A$61,0))),1,"")
A13: 1.8 | B13: 기획 발표자료에 최신 범위 반영 | C13: 오준탁 | D13: =IF(AND(D$8>=INDEX('작업 관리'!$E$9:$E$61,MATCH($A13,'작업 관리'!$A$9:$A$61,0)),D$8<=INDEX('작업 관리'!$F$9:$F$61,MATCH($A13,'작업 관리'!$A$9:$A$61,0))),1,"") | E13: =IF(AND(E$8>=INDEX('작업 관리'!$E$9:$E$61,MATCH($A13,'작업 관리'!$A$9:$A$61,0)),E$8<=INDEX('작업 관리'!$F$9:$F$61,MATCH($A13,'작업 관리'!$A$9:$A$61,0))),1,"") -> 1 | F13: =IF(AND(F$8>=INDEX('작업 관리'!$E$9:$E$61,MATCH($A13,'작업 관리'!$A$9:$A$61,0)),F$8<=INDEX('작업 관리'!$F$9:$F$61,MATCH($A13,'작업 관리'!$A$9:$A$61,0))),1,"") -> 1 | G13: =IF(AND(G$8>=INDEX('작업 관리'!$E$9:$E$61,MATCH($A13,'작업 관리'!$A$9:$A$61,0)),G$8<=INDEX('작업 관리'!$F$9:$F$61,MATCH($A13,'작업 관리'!$A$9:$A$61,0))),1,"") | H13: =IF(AND(H$8>=INDEX('작업 관리'!$E$9:$E$61,MATCH($A13,'작업 관리'!$A$9:$A$61,0)),H$8<=INDEX('작업 관리'!$F$9:$F$61,MATCH($A13,'작업 관리'!$A$9:$A$61,0))),1,"") | I13: =IF(AND(I$8>=INDEX('작업 관리'!$E$9:$E$61,MATCH($A13,'작업 관리'!$A$9:$A$61,0)),I$8<=INDEX('작업 관리'!$F$9:$F$61,MATCH($A13,'작업 관리'!$A$9:$A$61,0))),1,"") | J13: =IF(AND(J$8>=INDEX('작업 관리'!$E$9:$E$61,MATCH($A13,'작업 관리'!$A$9:$A$61,0)),J$8<=INDEX('작업 관리'!$F$9:$F$61,MATCH($A13,'작업 관리'!$A$9:$A$61,0))),1,"") | K13: =IF(AND(K$8>=INDEX('작업 관리'!$E$9:$E$61,MATCH($A13,'작업 관리'!$A$9:$A$61,0)),K$8<=INDEX('작업 관리'!$F$9:$F$61,MATCH($A13,'작업 관리'!$A$9:$A$61,0))),1,"") | ... S13: =IF(AND(S$8>=INDEX('작업 관리'!$E$9:$E$61,MATCH($A13,'작업 관리'!$A$9:$A$61,0)),S$8<=INDEX('작업 관리'!$F$9:$F$61,MATCH($A13,'작업 관리'!$A$9:$A$61,0))),1,"")
A14: 1.M1 | B14: 업종·데이터·모델 설계 기준 확정 | C14: 김동혁 | D14: =IF(AND(D$8>=INDEX('작업 관리'!$E$9:$E$61,MATCH($A14,'작업 관리'!$A$9:$A$61,0)),D$8<=INDEX('작업 관리'!$F$9:$F$61,MATCH($A14,'작업 관리'!$A$9:$A$61,0))),1,"") | E14: =IF(AND(E$8>=INDEX('작업 관리'!$E$9:$E$61,MATCH($A14,'작업 관리'!$A$9:$A$61,0)),E$8<=INDEX('작업 관리'!$F$9:$F$61,MATCH($A14,'작업 관리'!$A$9:$A$61,0))),1,"") | F14: =IF(AND(F$8>=INDEX('작업 관리'!$E$9:$E$61,MATCH($A14,'작업 관리'!$A$9:$A$61,0)),F$8<=INDEX('작업 관리'!$F$9:$F$61,MATCH($A14,'작업 관리'!$A$9:$A$61,0))),1,"") -> 1 | G14: =IF(AND(G$8>=INDEX('작업 관리'!$E$9:$E$61,MATCH($A14,'작업 관리'!$A$9:$A$61,0)),G$8<=INDEX('작업 관리'!$F$9:$F$61,MATCH($A14,'작업 관리'!$A$9:$A$61,0))),1,"") | H14: =IF(AND(H$8>=INDEX('작업 관리'!$E$9:$E$61,MATCH($A14,'작업 관리'!$A$9:$A$61,0)),H$8<=INDEX('작업 관리'!$F$9:$F$61,MATCH($A14,'작업 관리'!$A$9:$A$61,0))),1,"") | I14: =IF(AND(I$8>=INDEX('작업 관리'!$E$9:$E$61,MATCH($A14,'작업 관리'!$A$9:$A$61,0)),I$8<=INDEX('작업 관리'!$F$9:$F$61,MATCH($A14,'작업 관리'!$A$9:$A$61,0))),1,"") | J14: =IF(AND(J$8>=INDEX('작업 관리'!$E$9:$E$61,MATCH($A14,'작업 관리'!$A$9:$A$61,0)),J$8<=INDEX('작업 관리'!$F$9:$F$61,MATCH($A14,'작업 관리'!$A$9:$A$61,0))),1,"") | K14: =IF(AND(K$8>=INDEX('작업 관리'!$E$9:$E$61,MATCH($A14,'작업 관리'!$A$9:$A$61,0)),K$8<=INDEX('작업 관리'!$F$9:$F$61,MATCH($A14,'작업 관리'!$A$9:$A$61,0))),1,"") | ... S14: =IF(AND(S$8>=INDEX('작업 관리'!$E$9:$E$61,MATCH($A14,'작업 관리'!$A$9:$A$61,0)),S$8<=INDEX('작업 관리'!$F$9:$F$61,MATCH($A14,'작업 관리'!$A$9:$A$61,0))),1,"")
A15: 1.9 | B15: v2.3 연계 범위와 미정 결정 정리 | C15: 김동혁 | D15: =IF(AND(D$8>=INDEX('작업 관리'!$E$9:$E$61,MATCH($A15,'작업 관리'!$A$9:$A$61,0)),D$8<=INDEX('작업 관리'!$F$9:$F$61,MATCH($A15,'작업 관리'!$A$9:$A$61,0))),1,"") | E15: =IF(AND(E$8>=INDEX('작업 관리'!$E$9:$E$61,MATCH($A15,'작업 관리'!$A$9:$A$61,0)),E$8<=INDEX('작업 관리'!$F$9:$F$61,MATCH($A15,'작업 관리'!$A$9:$A$61,0))),1,"") | F15: =IF(AND(F$8>=INDEX('작업 관리'!$E$9:$E$61,MATCH($A15,'작업 관리'!$A$9:$A$61,0)),F$8<=INDEX('작업 관리'!$F$9:$F$61,MATCH($A15,'작업 관리'!$A$9:$A$61,0))),1,"") | G15: =IF(AND(G$8>=INDEX('작업 관리'!$E$9:$E$61,MATCH($A15,'작업 관리'!$A$9:$A$61,0)),G$8<=INDEX('작업 관리'!$F$9:$F$61,MATCH($A15,'작업 관리'!$A$9:$A$61,0))),1,"") -> 1 | H15: =IF(AND(H$8>=INDEX('작업 관리'!$E$9:$E$61,MATCH($A15,'작업 관리'!$A$9:$A$61,0)),H$8<=INDEX('작업 관리'!$F$9:$F$61,MATCH($A15,'작업 관리'!$A$9:$A$61,0))),1,"") | I15: =IF(AND(I$8>=INDEX('작업 관리'!$E$9:$E$61,MATCH($A15,'작업 관리'!$A$9:$A$61,0)),I$8<=INDEX('작업 관리'!$F$9:$F$61,MATCH($A15,'작업 관리'!$A$9:$A$61,0))),1,"") | J15: =IF(AND(J$8>=INDEX('작업 관리'!$E$9:$E$61,MATCH($A15,'작업 관리'!$A$9:$A$61,0)),J$8<=INDEX('작업 관리'!$F$9:$F$61,MATCH($A15,'작업 관리'!$A$9:$A$61,0))),1,"") | K15: =IF(AND(K$8>=INDEX('작업 관리'!$E$9:$E$61,MATCH($A15,'작업 관리'!$A$9:$A$61,0)),K$8<=INDEX('작업 관리'!$F$9:$F$61,MATCH($A15,'작업 관리'!$A$9:$A$61,0))),1,"") | ... S15: =IF(AND(S$8>=INDEX('작업 관리'!$E$9:$E$61,MATCH($A15,'작업 관리'!$A$9:$A$61,0)),S$8<=INDEX('작업 관리'!$F$9:$F$61,MATCH($A15,'작업 관리'!$A$9:$A$61,0))),1,"")
A16: 1.10 | B16: 6개 판단 관점·업종 지표·징후 기준 정리 | C16: 오준탁 | D16: =IF(AND(D$8>=INDEX('작업 관리'!$E$9:$E$61,MATCH($A16,'작업 관리'!$A$9:$A$61,0)),D$8<=INDEX('작업 관리'!$F$9:$F$61,MATCH($A16,'작업 관리'!$A$9:$A$61,0))),1,"") | E16: =IF(AND(E$8>=INDEX('작업 관리'!$E$9:$E$61,MATCH($A16,'작업 관리'!$A$9:$A$61,0)),E$8<=INDEX('작업 관리'!$F$9:$F$61,MATCH($A16,'작업 관리'!$A$9:$A$61,0))),1,"") | F16: =IF(AND(F$8>=INDEX('작업 관리'!$E$9:$E$61,MATCH($A16,'작업 관리'!$A$9:$A$61,0)),F$8<=INDEX('작업 관리'!$F$9:$F$61,MATCH($A16,'작업 관리'!$A$9:$A$61,0))),1,"") | G16: =IF(AND(G$8>=INDEX('작업 관리'!$E$9:$E$61,MATCH($A16,'작업 관리'!$A$9:$A$61,0)),G$8<=INDEX('작업 관리'!$F$9:$F$61,MATCH($A16,'작업 관리'!$A$9:$A$61,0))),1,"") -> 1 | H16: =IF(AND(H$8>=INDEX('작업 관리'!$E$9:$E$61,MATCH($A16,'작업 관리'!$A$9:$A$61,0)),H$8<=INDEX('작업 관리'!$F$9:$F$61,MATCH($A16,'작업 관리'!$A$9:$A$61,0))),1,"") -> 1 | I16: =IF(AND(I$8>=INDEX('작업 관리'!$E$9:$E$61,MATCH($A16,'작업 관리'!$A$9:$A$61,0)),I$8<=INDEX('작업 관리'!$F$9:$F$61,MATCH($A16,'작업 관리'!$A$9:$A$61,0))),1,"") -> 1 | J16: =IF(AND(J$8>=INDEX('작업 관리'!$E$9:$E$61,MATCH($A16,'작업 관리'!$A$9:$A$61,0)),J$8<=INDEX('작업 관리'!$F$9:$F$61,MATCH($A16,'작업 관리'!$A$9:$A$61,0))),1,"") | K16: =IF(AND(K$8>=INDEX('작업 관리'!$E$9:$E$61,MATCH($A16,'작업 관리'!$A$9:$A$61,0)),K$8<=INDEX('작업 관리'!$F$9:$F$61,MATCH($A16,'작업 관리'!$A$9:$A$61,0))),1,"") | ... S16: =IF(AND(S$8>=INDEX('작업 관리'!$E$9:$E$61,MATCH($A16,'작업 관리'!$A$9:$A$61,0)),S$8<=INDEX('작업 관리'!$F$9:$F$61,MATCH($A16,'작업 관리'!$A$9:$A$61,0))),1,"")
A17: 2.7 | B17: 위험 사건 이력 수집과 원문 대조 | C17: 김동혁 | D17: =IF(AND(D$8>=INDEX('작업 관리'!$E$9:$E$61,MATCH($A17,'작업 관리'!$A$9:$A$61,0)),D$8<=INDEX('작업 관리'!$F$9:$F$61,MATCH($A17,'작업 관리'!$A$9:$A$61,0))),1,"") | E17: =IF(AND(E$8>=INDEX('작업 관리'!$E$9:$E$61,MATCH($A17,'작업 관리'!$A$9:$A$61,0)),E$8<=INDEX('작업 관리'!$F$9:$F$61,MATCH($A17,'작업 관리'!$A$9:$A$61,0))),1,"") | F17: =IF(AND(F$8>=INDEX('작업 관리'!$E$9:$E$61,MATCH($A17,'작업 관리'!$A$9:$A$61,0)),F$8<=INDEX('작업 관리'!$F$9:$F$61,MATCH($A17,'작업 관리'!$A$9:$A$61,0))),1,"") -> 1 | G17: =IF(AND(G$8>=INDEX('작업 관리'!$E$9:$E$61,MATCH($A17,'작업 관리'!$A$9:$A$61,0)),G$8<=INDEX('작업 관리'!$F$9:$F$61,MATCH($A17,'작업 관리'!$A$9:$A$61,0))),1,"") -> 1 | H17: =IF(AND(H$8>=INDEX('작업 관리'!$E$9:$E$61,MATCH($A17,'작업 관리'!$A$9:$A$61,0)),H$8<=INDEX('작업 관리'!$F$9:$F$61,MATCH($A17,'작업 관리'!$A$9:$A$61,0))),1,"") | I17: =IF(AND(I$8>=INDEX('작업 관리'!$E$9:$E$61,MATCH($A17,'작업 관리'!$A$9:$A$61,0)),I$8<=INDEX('작업 관리'!$F$9:$F$61,MATCH($A17,'작업 관리'!$A$9:$A$61,0))),1,"") | J17: =IF(AND(J$8>=INDEX('작업 관리'!$E$9:$E$61,MATCH($A17,'작업 관리'!$A$9:$A$61,0)),J$8<=INDEX('작업 관리'!$F$9:$F$61,MATCH($A17,'작업 관리'!$A$9:$A$61,0))),1,"") | K17: =IF(AND(K$8>=INDEX('작업 관리'!$E$9:$E$61,MATCH($A17,'작업 관리'!$A$9:$A$61,0)),K$8<=INDEX('작업 관리'!$F$9:$F$61,MATCH($A17,'작업 관리'!$A$9:$A$61,0))),1,"") | ... S17: =IF(AND(S$8>=INDEX('작업 관리'!$E$9:$E$61,MATCH($A17,'작업 관리'!$A$9:$A$61,0)),S$8<=INDEX('작업 관리'!$F$9:$F$61,MATCH($A17,'작업 관리'!$A$9:$A$61,0))),1,"")
A18: 2.1 | B18: 재무·공시 수집과 출처 저장 | C18: 김동혁 | D18: =IF(AND(D$8>=INDEX('작업 관리'!$E$9:$E$61,MATCH($A18,'작업 관리'!$A$9:$A$61,0)),D$8<=INDEX('작업 관리'!$F$9:$F$61,MATCH($A18,'작업 관리'!$A$9:$A$61,0))),1,"") | E18: =IF(AND(E$8>=INDEX('작업 관리'!$E$9:$E$61,MATCH($A18,'작업 관리'!$A$9:$A$61,0)),E$8<=INDEX('작업 관리'!$F$9:$F$61,MATCH($A18,'작업 관리'!$A$9:$A$61,0))),1,"") | F18: =IF(AND(F$8>=INDEX('작업 관리'!$E$9:$E$61,MATCH($A18,'작업 관리'!$A$9:$A$61,0)),F$8<=INDEX('작업 관리'!$F$9:$F$61,MATCH($A18,'작업 관리'!$A$9:$A$61,0))),1,"") | G18: =IF(AND(G$8>=INDEX('작업 관리'!$E$9:$E$61,MATCH($A18,'작업 관리'!$A$9:$A$61,0)),G$8<=INDEX('작업 관리'!$F$9:$F$61,MATCH($A18,'작업 관리'!$A$9:$A$61,0))),1,"") -> 1 | H18: =IF(AND(H$8>=INDEX('작업 관리'!$E$9:$E$61,MATCH($A18,'작업 관리'!$A$9:$A$61,0)),H$8<=INDEX('작업 관리'!$F$9:$F$61,MATCH($A18,'작업 관리'!$A$9:$A$61,0))),1,"") -> 1 | I18: =IF(AND(I$8>=INDEX('작업 관리'!$E$9:$E$61,MATCH($A18,'작업 관리'!$A$9:$A$61,0)),I$8<=INDEX('작업 관리'!$F$9:$F$61,MATCH($A18,'작업 관리'!$A$9:$A$61,0))),1,"") | J18: =IF(AND(J$8>=INDEX('작업 관리'!$E$9:$E$61,MATCH($A18,'작업 관리'!$A$9:$A$61,0)),J$8<=INDEX('작업 관리'!$F$9:$F$61,MATCH($A18,'작업 관리'!$A$9:$A$61,0))),1,"") | K18: =IF(AND(K$8>=INDEX('작업 관리'!$E$9:$E$61,MATCH($A18,'작업 관리'!$A$9:$A$61,0)),K$8<=INDEX('작업 관리'!$F$9:$F$61,MATCH($A18,'작업 관리'!$A$9:$A$61,0))),1,"") | ... S18: =IF(AND(S$8>=INDEX('작업 관리'!$E$9:$E$61,MATCH($A18,'작업 관리'!$A$9:$A$61,0)),S$8<=INDEX('작업 관리'!$F$9:$F$61,MATCH($A18,'작업 관리'!$A$9:$A$61,0))),1,"")
A19: 2.2 | B19: 계정 매핑과 비교 기준 정렬 | C19: 김동민 | D19: =IF(AND(D$8>=INDEX('작업 관리'!$E$9:$E$61,MATCH($A19,'작업 관리'!$A$9:$A$61,0)),D$8<=INDEX('작업 관리'!$F$9:$F$61,MATCH($A19,'작업 관리'!$A$9:$A$61,0))),1,"") | E19: =IF(AND(E$8>=INDEX('작업 관리'!$E$9:$E$61,MATCH($A19,'작업 관리'!$A$9:$A$61,0)),E$8<=INDEX('작업 관리'!$F$9:$F$61,MATCH($A19,'작업 관리'!$A$9:$A$61,0))),1,"") | F19: =IF(AND(F$8>=INDEX('작업 관리'!$E$9:$E$61,MATCH($A19,'작업 관리'!$A$9:$A$61,0)),F$8<=INDEX('작업 관리'!$F$9:$F$61,MATCH($A19,'작업 관리'!$A$9:$A$61,0))),1,"") | G19: =IF(AND(G$8>=INDEX('작업 관리'!$E$9:$E$61,MATCH($A19,'작업 관리'!$A$9:$A$61,0)),G$8<=INDEX('작업 관리'!$F$9:$F$61,MATCH($A19,'작업 관리'!$A$9:$A$61,0))),1,"") -> 1 | H19: =IF(AND(H$8>=INDEX('작업 관리'!$E$9:$E$61,MATCH($A19,'작업 관리'!$A$9:$A$61,0)),H$8<=INDEX('작업 관리'!$F$9:$F$61,MATCH($A19,'작업 관리'!$A$9:$A$61,0))),1,"") -> 1 | I19: =IF(AND(I$8>=INDEX('작업 관리'!$E$9:$E$61,MATCH($A19,'작업 관리'!$A$9:$A$61,0)),I$8<=INDEX('작업 관리'!$F$9:$F$61,MATCH($A19,'작업 관리'!$A$9:$A$61,0))),1,"") | J19: =IF(AND(J$8>=INDEX('작업 관리'!$E$9:$E$61,MATCH($A19,'작업 관리'!$A$9:$A$61,0)),J$8<=INDEX('작업 관리'!$F$9:$F$61,MATCH($A19,'작업 관리'!$A$9:$A$61,0))),1,"") | K19: =IF(AND(K$8>=INDEX('작업 관리'!$E$9:$E$61,MATCH($A19,'작업 관리'!$A$9:$A$61,0)),K$8<=INDEX('작업 관리'!$F$9:$F$61,MATCH($A19,'작업 관리'!$A$9:$A$61,0))),1,"") | ... S19: =IF(AND(S$8>=INDEX('작업 관리'!$E$9:$E$61,MATCH($A19,'작업 관리'!$A$9:$A$61,0)),S$8<=INDEX('작업 관리'!$F$9:$F$61,MATCH($A19,'작업 관리'!$A$9:$A$61,0))),1,"")
A20: 2.8 | B20: 과거 재무·주석 학습자료 수집 | C20: 김동혁 | D20: =IF(AND(D$8>=INDEX('작업 관리'!$E$9:$E$61,MATCH($A20,'작업 관리'!$A$9:$A$61,0)),D$8<=INDEX('작업 관리'!$F$9:$F$61,MATCH($A20,'작업 관리'!$A$9:$A$61,0))),1,"") | E20: =IF(AND(E$8>=INDEX('작업 관리'!$E$9:$E$61,MATCH($A20,'작업 관리'!$A$9:$A$61,0)),E$8<=INDEX('작업 관리'!$F$9:$F$61,MATCH($A20,'작업 관리'!$A$9:$A$61,0))),1,"") | F20: =IF(AND(F$8>=INDEX('작업 관리'!$E$9:$E$61,MATCH($A20,'작업 관리'!$A$9:$A$61,0)),F$8<=INDEX('작업 관리'!$F$9:$F$61,MATCH($A20,'작업 관리'!$A$9:$A$61,0))),1,"") | G20: =IF(AND(G$8>=INDEX('작업 관리'!$E$9:$E$61,MATCH($A20,'작업 관리'!$A$9:$A$61,0)),G$8<=INDEX('작업 관리'!$F$9:$F$61,MATCH($A20,'작업 관리'!$A$9:$A$61,0))),1,"") -> 1 | H20: =IF(AND(H$8>=INDEX('작업 관리'!$E$9:$E$61,MATCH($A20,'작업 관리'!$A$9:$A$61,0)),H$8<=INDEX('작업 관리'!$F$9:$F$61,MATCH($A20,'작업 관리'!$A$9:$A$61,0))),1,"") -> 1 | I20: =IF(AND(I$8>=INDEX('작업 관리'!$E$9:$E$61,MATCH($A20,'작업 관리'!$A$9:$A$61,0)),I$8<=INDEX('작업 관리'!$F$9:$F$61,MATCH($A20,'작업 관리'!$A$9:$A$61,0))),1,"") | J20: =IF(AND(J$8>=INDEX('작업 관리'!$E$9:$E$61,MATCH($A20,'작업 관리'!$A$9:$A$61,0)),J$8<=INDEX('작업 관리'!$F$9:$F$61,MATCH($A20,'작업 관리'!$A$9:$A$61,0))),1,"") | K20: =IF(AND(K$8>=INDEX('작업 관리'!$E$9:$E$61,MATCH($A20,'작업 관리'!$A$9:$A$61,0)),K$8<=INDEX('작업 관리'!$F$9:$F$61,MATCH($A20,'작업 관리'!$A$9:$A$61,0))),1,"") | ... S20: =IF(AND(S$8>=INDEX('작업 관리'!$E$9:$E$61,MATCH($A20,'작업 관리'!$A$9:$A$61,0)),S$8<=INDEX('작업 관리'!$F$9:$F$61,MATCH($A20,'작업 관리'!$A$9:$A$61,0))),1,"")
... A61: 6.M6 | B61: 프로젝트 발표 | C61: 오준탁 | D61: =IF(AND(D$8>=INDEX('작업 관리'!$E$9:$E$61,MATCH($A61,'작업 관리'!$A$9:$A$61,0)),D$8<=INDEX('작업 관리'!$F$9:$F$61,MATCH($A61,'작업 관리'!$A$9:$A$61,0))),1,"") | E61: =IF(AND(E$8>=INDEX('작업 관리'!$E$9:$E$61,MATCH($A61,'작업 관리'!$A$9:$A$61,0)),E$8<=INDEX('작업 관리'!$F$9:$F$61,MATCH($A61,'작업 관리'!$A$9:$A$61,0))),1,"") | F61: =IF(AND(F$8>=INDEX('작업 관리'!$E$9:$E$61,MATCH($A61,'작업 관리'!$A$9:$A$61,0)),F$8<=INDEX('작업 관리'!$F$9:$F$61,MATCH($A61,'작업 관리'!$A$9:$A$61,0))),1,"") | G61: =IF(AND(G$8>=INDEX('작업 관리'!$E$9:$E$61,MATCH($A61,'작업 관리'!$A$9:$A$61,0)),G$8<=INDEX('작업 관리'!$F$9:$F$61,MATCH($A61,'작업 관리'!$A$9:$A$61,0))),1,"") | H61: =IF(AND(H$8>=INDEX('작업 관리'!$E$9:$E$61,MATCH($A61,'작업 관리'!$A$9:$A$61,0)),H$8<=INDEX('작업 관리'!$F$9:$F$61,MATCH($A61,'작업 관리'!$A$9:$A$61,0))),1,"") | I61: =IF(AND(I$8>=INDEX('작업 관리'!$E$9:$E$61,MATCH($A61,'작업 관리'!$A$9:$A$61,0)),I$8<=INDEX('작업 관리'!$F$9:$F$61,MATCH($A61,'작업 관리'!$A$9:$A$61,0))),1,"") | J61: =IF(AND(J$8>=INDEX('작업 관리'!$E$9:$E$61,MATCH($A61,'작업 관리'!$A$9:$A$61,0)),J$8<=INDEX('작업 관리'!$F$9:$F$61,MATCH($A61,'작업 관리'!$A$9:$A$61,0))),1,"") | K61: =IF(AND(K$8>=INDEX('작업 관리'!$E$9:$E$61,MATCH($A61,'작업 관리'!$A$9:$A$61,0)),K$8<=INDEX('작업 관리'!$F$9:$F$61,MATCH($A61,'작업 관리'!$A$9:$A$61,0))),1,"") | ... S61: =IF(AND(S$8>=INDEX('작업 관리'!$E$9:$E$61,MATCH($A61,'작업 관리'!$A$9:$A$61,0)),S$8<=INDEX('작업 관리'!$F$9:$F$61,MATCH($A61,'작업 관리'!$A$9:$A$61,0))),1,"") -> 1

Sheet 완료 기준
A2: LoanSight AI 완료 기준 v1.4
A4: 작업별 산출물·완료 조건·근거와 관련 요구(R)·기능(F)·미정 질문(U)을 ID로 연결합니다.
A5: 주담당·계획은 작업 관리, 산출물·근거·연결은 같은 ID 기준입니다.
A6: 주담당은 작업 관리에서 확인합니다. 기존 노션의 팀 메모는 보존하며 Markdown 상세에도 포함합니다.
A8: ID | B8: 작업 | C8: 협업 | D8: 선행 ID | E8: 산출물 | F8: 완료 기준 | G8: 완료근거 | H8: 관련 요구사항 | I8: 관련 기능 | J8: 미정 질문
A9: 1.3 | B9: 범위와 역할 분담 합의 | C9: 전원 | D9: 1.1 | E9: 범위·담당 확정 기록 | F9: 4개 업종·상환/연체 위험 사건 예측·주석/위험 패널 필수 범위와 5명 역할을 확인한다. 세부 배정·공수·백업·날짜의 최종 팀 합의를 기록한다. | G9: 2026.10.28 검토: Slack 10/27 작업기록·현직자 Q&A 및 기획안 v2.1에서 부분 진행 확인. 세부 합의는 남아 있음. https://kb-bridge12.slack.com/archives/C0C8L1KGVN1/p1793085285671109 | H9: N-R01/N-R16/N-R30 | J9: N-U08
A10: 1.4 | B10: 확정 4개 업종과 수집 범위 점검 | C10: 김동혁 | D10: 1.1 | E10: 업종 매핑·대상 제외·수집 범위표 | F10: 제조·건설·도소매·부동산 임대 4개를 DART 코드로 매핑하고 금융/보험·지주·스팩·운수/창고·장비/물품 렌탈·부동산 관리/중개를 제외한다. 세부분류·겸업 기준과 기간은 미정으로 표시한다. | G10: 2026.10.28 검토: Slack 10/27 작업기록·현직자 Q&A 및 기획안 v2.1에서 부분 진행 확인. 세부 합의는 남아 있음. https://kb-bridge12.slack.com/archives/C0C8L1KGVN1/p1793085285671109 | H10: N-R01/N-R32 | I10: N-F01/N-F30 | J10: N-U02/N-U15
A11: 1.6 | B11: 재무비율·계정·업종 계산 기준 정의 | C11: 김동민 | D11: 1.1 | E11: 비율 산식·계정·예외·근거 사전 | F11: 차입금·EBITDA·이자비용·현금흐름·회전율/회전일수의 산식과 출처를 정리한다. 평균/기말 잔액·금융원가 근사·임대보증금 포함 여부는 미정으로 남기고 0/음수/결측 처리 기준을 구분한다. | G11: 2026.10.28 검토: Slack 10/27 작업기록·현직자 Q&A 및 기획안 v2.1에서 부분 진행 확인. 세부 합의는 남아 있음. https://kb-bridge12.slack.com/archives/C0C8L1KGVN1/p1793085285671109 | H11: N-R05/N-R07/N-R09/N-R33/N-R34/N-R35 | I11: N-F31/N-F32/N-F33 | J11: N-U11/N-U13/N-U14
A12: 1.7 | B12: 상환·연체 위험 사건과 12개월 라벨 정의 | C12: 김동민 | D12: 1.1 | E12: 복합 위험 사건·기준일·추적 기간 명세 | F12: 원리금 실제 연체/기한이익상실·지급거절·회생/채권은행 관리절차 신청·감사의견 변형/계속기업 불확실성을 유형별 기록한다. 상환과 무관한 관리종목/상장폐지는 제외한다. 유형별 심각도·사건/특징 역할·시점·비발생 판정은 원문 근거와 함께 합의한다. | G12: 2026.10.28 검토: Slack 10/27 작업기록·현직자 Q&A 및 기획안 v2.1에서 부분 진행 확인. 세부 합의는 남아 있음. https://kb-bridge12.slack.com/archives/C0C8L1KGVN1/p1793085285671109 | H12: N-R16/N-R17/N-R18 | I12: N-F13/N-F14 | J12: N-U01
A13: 1.8 | B13: 기획 발표자료에 최신 범위 반영 | C13: 최수인 | D13: 1.1 | E13: 기획안 v2.3 기준 발표 개정 초안 | F13: 상환·연체 위험 사건 목표, 4개 업종·렌탈 제외, 징후 판정 규칙·주석 추출·논리 화면 7개를 반영한다. 기존 발표자료와 화면설계서 원본은 보존한다. | H13: N-R01/N-R16/N-R38/N-R39/N-R40/N-R41/N-R42/N-R43 | J13: N-U02
A14: 1.M1 | B14: 업종·데이터·모델 설계 기준 확정 | C14: 전원 | D14: 1.3, 1.6, 1.7 | E14: 1차 범위 결정 기록 | F14: 4개 업종 매핑·분석 기간·산식·위험 사건/관측 창의 결정 여부를 정리한다. 미정 사항은 미정으로 유지한다. | G14: 2026.10.28 검토: Slack 10/27 작업기록·현직자 Q&A 및 기획안 v2.1에서 부분 진행 확인. 세부 합의는 남아 있음. https://kb-bridge12.slack.com/archives/C0C8L1KGVN1/p1793085285671109 | H14: N-R01/N-R16/N-R17/N-R18/N-R32/N-R33 | J14: N-U02
A15: 1.9 | B15: v2.3 연계 범위와 미정 결정 정리 | C15: 전원 | D15: 1.1 | E15: 변경/충돌·미정 질문 20개·범위 기록 | F15: v2.0 계열 통합 기획안 v2.3을 기준으로 문서 범위·징후 규칙과 미정을 정리한다. 연결(CFS) 우선·미확보 시 별도(OFS) 전환은 v2.3과 최신 사용자 결정을 따른다. 화면설계서는 변경하지 않는다. | H15: N-R01/N-R16/N-R30/N-R31 | I15: N-F27/N-F28/N-F29 | J15: N-U02/N-U04/N-U06/N-U07/N-U08/N-U10/N-U11/N-U12/N-U13/N-U14/N-U15/N-U16/N-U17/N-U18/N-U20
A16: 1.10 | B16: 6개 판단 관점·업종 지표·징후 기준 정리 | C16: 김동민·최수인 | D16: 1.9 | E16: 6축 지표·경고/주의/관찰 초안·근거/미정표 | F16: 은행 자산건전성 분류(FLC)·신용위험 평가 관점의 6개 판단 축(상환재원, 유동성·만기, 재무구조, 우발·부외 부담, 외부 평가, 담보·회수 여력)에 공시 지표와 주석 근거를 연결한다. 업종별 핵심 지표(우선순위 5개)·보조 지표·그대로 쓰면 왜곡되는 지표를 정의한다. 공통: 영업이익률, 영업CF÷영업이익, 이자보상비율, 자본잠식. 제조: 현금전환주기, 재고·매출채권 증가율−매출증가율, 영업CF÷영업이익, CAPEX÷영업CF, 이자보상비율. 도소매: 매출총이익률 변화, 재고자산회전율, 매입채무 지급일수 변화, 현금전환주기, 리스부채 포함 부채비율. 건설: 계약자산 증가율−매출증가율, 공사미수금 회수기간, 공사원가율, PF 보증·조건부 의무÷자기자본과 1년 내 만기 PF 비중, 영업CF 대 유동부채. 부동산 임대: EBITDA 이자보상배율, 차입금÷투자부동산, 1년 내 만기 차입 비중, 현금보상비율, 평균 조달금리. 대상 업종은 기획안 v2.0의 4개 업종(제조·도소매·건설·부동산 임대)이며 장비·물품 렌탈은 범위에서 제외한다. | H16: N-R14/N-R24/N-R36/N-R38/N-R39 | I16: N-F21/N-F34/N-F36/N-F37 | J16: N-U06/N-U12/N-U17
A17: 2.7 | B17: 위험 사건 이력 수집과 원문 대조 | C17: 최수인 | D17: 1.7 | E17: 위험 사건별 이력·사건일·공시 원문 | F17: 주요사항보고서·감사보고서·기한이익상실 공시를 대조하고 유형·사건일·최초 공개일·접수번호를 보존한다. API 미조회만으로 비발생을 단정하지 않고 제공 기간·기업 범위·누락/실패를 기록한다. | H17: N-R17/N-R18 | I17: N-F13/N-F14 | J17: N-U01
A18: 2.1 | B18: 재무·공시 수집과 출처 저장 | C18: 서종원 | D18: 1.M1 | E18: 수집 응답·공시 목록·캐시 | F18: 기업·업종·보고서·접수번호·공시일·수집일·원본·버전·정정 관계를 보존한다. 공개 당시 알 수 있는 데이터만 모델 시점에 연결하고 실패/캐시 정책은 별도 기록한다. | H18: N-R03/N-R27/N-R30 | I18: N-F02/N-F24/N-F27 | J18: N-U08
A19: 2.2 | B19: 계정 매핑과 비교 기준 정렬 | C19: 오준탁 | D19: 1.M1 | E19: 계정 매핑·표준 데이터 | F19: 연결재무제표(CFS)를 우선 사용하고 없으면 별도재무제표(OFS)로 전환해 화면에 표시한다. 기간 비교 시 연결·별도, 통화·단위·보고 기간·누적/당분기 기준을 맞춘다. 회계 기준이 다른 값을 하나의 추세로 혼합하지 않는다. 정정공시 적용 여부·버전과 자료 미확보를 표시한다. | H19: N-R04/N-R05/N-R33 | I19: N-F03/N-F31 | J19: N-U11/N-U13/N-U14
A20: 2.8 | B20: 과거 재무·주석 학습자료 수집 | C20: 김동민 | D20: 1.M1 | E20: 기업·공시시점별 학습 원자료 | F20: 기업·공시시점별 재무와 주석을 수집하고 원본 버전·회계 범위·공개일·관측 상태를 저장한다. | H20: N-R03/N-R18/N-R19 | I20: N-F02/N-F14/N-F15 | J20: N-U04
A21: 2.3 | B21: 주석 구간·교차참조·출처 확보 | C21: 최수인 | D21: 2.1 | E21: 관련 주석 원문 표본 | F21: 공통/업종별 주석 구간의 표·본문·교차참조·중복과 원문 위치를 기록한다. 장비·물품 렌탈은 제외한다. | H21: N-R11/N-R41/N-R42/N-R43 | I21: N-F09/N-F39/N-F40/N-F41 | J21: N-U04/N-U18
A22: 2.9 | B22: 12개월 라벨과 관측기간 구성 | C22: 최수인 | D22: 2.7, 2.8 | E22: 모델 학습·평가 표본 명세 | F22: 공개 기준일 이후 12개월의 위험 사건·비발생·추적 미완료를 구분한다. 충분한 추적 종료 전에는 정상 라벨을 부여하지 않고 사건 발생 시점과 입력 시점을 보존한다. | H22: N-R16/N-R18 | I22: N-F14 | J22: N-U01
A23: 2.11 | B23: 주석 원문 구간·추출 검출 상태 저장 | C23: 김동민·최수인 | D23: 1.9, 2.1 | E23: 원문 구간·교차참조·구조화/검출 상태 저장 구조 | F23: 보고서/구간·접수번호·공개일·버전·현재/전기·방향·한도/잔액·검수·검출/공시상 없음/미검출/추출 실패를 분리한다. 공시상 없음은 명시 원문이 있어야 하며 금액 미기재/실패를 0으로 바꾸지 않는다. | H23: N-R03/N-R12/N-R27/N-R41/N-R42/N-R43 | I23: N-F02/N-F10/N-F24/N-F39/N-F40/N-F41 | J23: N-U04/N-U08/N-U18
A24: 2.4 | B24: 데이터 정합성과 결측 점검 | C24: 김동혁 | D24: 2.1, 2.2 | E24: 품질 점검 결과 | F24: 자산·부채·자본 합계, 부호·통화·단위·계정 매핑·결측/0을 처리한다. 원문과 계산값의 연결 및 자료 미확보 상태를 기록한다. | H24: N-R05 | I24: N-F03
A25: 2.6 | B25: 업종 비교 표본 확보와 정리 | C25: 김동혁 | D25: 2.4 | E25: 비교 기업·기간·표본 수 | F25: 동일 업종·기간·회계 기준의 비교 기업·분포·표본 수를 표시한다. 표본 부족은 비교 불가로 표시하며 한국은행 평균의 업종 수준·연도·모집단 차이는 N-U16 결정 후 적용한다. | H25: N-R10/N-R40 | I25: N-F08/N-F38 | J25: N-U06/N-U16/N-U20
A26: 3.2 | B26: 기업 검색과 업종 표시·필터 | C26: 김동혁 | D26: 1.M1 | E26: 검색·업종 선택 화면 | F26: 기업 식별·DART 업종코드·서비스 업종·세부분류·적용 기준·보고 기간·연결/별도·결산월을 표시한다. 수동 업종 변경과 근거는 3.12에 연결한다. | H26: N-R01/N-R02/N-R32 | I26: N-F01/N-F30 | J26: N-U02/N-U15
A27: 3.1 | B27: 변동 기여도와 재무비율 계산 | C27: 서종원 | D27: 1.M1 | E27: 계산 로직·검산 결과 | F27: 영업이익 변동 금액·기여도·잔차와 0/음수 분모·적자 전환·결측을 검산한다. 숫자 분해를 인과관계로 단정하지 않는다. | H27: N-R08/N-R09 | I27: N-F06/N-F07
A28: 3.12 | B28: 겸업 판정·업종 변경 근거 기록 | C28: 오준탁·김동민 | D28: 1.9, 3.2 | E28: DART 매핑·복합 판정·수동 변경 기록 | F28: 기업/업종/세부분류와 건설/부동산 임대 적용 기준을 표시한다. 복합 판정 매출 비중·권한/저장은 N-U15 합의 후 적용하고 담당자 변경 사유·근거를 보존해 변경 업종 기준으로 다시 분석한다. | H28: N-R01/N-R02/N-R32 | I28: N-F01/N-F30 | J28: N-U02/N-U15
A29: 3.3 | B29: 핵심 재무 대시보드와 차트 | C29: 김동민 | D29: 3.2, 1.6 | E29: 영업이익·변동·현금흐름 화면 | F29: 영업이익 우선 배치·업종별 감가상각 강조·차입/상환능력·운전자본·기간/회계 범위/원문을 표시한다. 신규 업종 패널은 기존 N-S04에 붙이고 화면을 별도 신설하지 않는다. | H29: N-R07/N-R09/N-R27/N-R33/N-R34/N-R35/N-R38/N-R40 | I29: N-F05/N-F07/N-F24/N-F32/N-F33/N-F36/N-F38 | J29: N-U20
A30: 3.8 | B30: 차입 상환능력·영업순환 지표 계산 | C30: 서종원·오준탁 | D30: 1.6, 2.4 | E30: 차입/상환·CCC·운전자본 계산·검산 기록 | F30: 차입금/EBITDA/이자보상과 업종별 회전율·일수·현금전환주기를 산출한다. | H30: N-R07/N-R09/N-R33/N-R34/N-R35 | I30: N-F05/N-F07/N-F31/N-F32/N-F33 | J30: N-U11/N-U13/N-U14
A31: 3.4 | B31: 확인 체크와 재무 검토 기록 초안 | C31: 오준탁 | D31: 3.3 | E31: 확인 기록·메모 초안 | F31: 규칙 징후 단계·모델 확률·담당자 확인 상태를 별도로 저장/표시한다. 미확인 모음과 근거/수치 복사·수정 및 내부 추가 확인 안내를 제공한다. | H31: N-R14/N-R24/N-R25/N-R26/N-R27/N-R39/N-R43 | I31: N-F21/N-F22/N-F23/N-F24/N-F37/N-F41 | J31: N-U08/N-U17
A32: 3.6 | B32: 업종별 확인 기준 검토 | C32: 최수인 | D32: 2.4 | E32: 업종별 점검 기준 | F32: 6개 판단 관점·업종별 핵심 지표와 원문 근거를 연결하고 v2.3 징후 기준을 검토한다. 수치는 팀 가설이며 공식 은행 기준을 대신하지 않는다. | H32: N-R14/N-R24/N-R36/N-R38/N-R39 | I32: N-F21/N-F34/N-F36/N-F37 | J32: N-U06/N-U12/N-U17
A33: 3.9 | B33: 업종 위험 지표·징후 단계 판정 연결 | C33: 오준탁·서종원 | D33: 1.10, 3.8 | E33: 업종별 지표·규칙 버전·단계/판정 근거 | F33: 경고: 감사의견 비적정·계속기업 관련 중요한 불확실성, 자기자본≤0, 어음·수표 지급거절·회생절차 개시신청 공시, 기한이익상실 사유 발생, 이자보상비율<1배 직전 3년 연속. 주의: 0<자기자본<납입자본금, 당기 이자보상비율<1배, 흑자인데 영업CF 2년 연속 음수, 1년 내 만기 차입금>현금성자산+영업CF. 관찰: 업종 중앙값 대비 열위·전기 대비 악화 추세. · 판정 순서: ① 공시 원문에 사건으로 기재되면 경고, ② 이자보상비율 1배 미만이 직전 3년 연속이면 경고, ③ 업종과 무관한 절대 경계(1배·0·납입자본금·상환재원)를 당기에 넘으면 주의, ④ 업종 중앙값·전기 대비 상대적으로 열위·악화하면 관찰로 표시한다. 위에서부터 처음 해당하는 단계로 확정한다. · 데이터 상태: 근사·추정 값은 단계를 유지하고 ‘근사’ 표시만 붙인다. 미확보·미검출 항목은 단계를 판정하지 않으며 ‘없음’으로 처리하지 않는다. · 중복 방지: 같은 원인에서 생긴 신호(예: 영업손실로 인한 이자보상비율 1배 미만)는 1건으로 표시하고 근거에 관련 지표를 함께 적는다. 사건으로 판정된 경고는 금액·업종 특성과 무관하게 단계를 낮추지 않는다. · 제외 항목: 신용등급 하향·부정적 전망, 제공 보증·조건부 의무의 자기자본 대비 급증은 판정 기준의 근거가 확인될 때까지 단계 기준에서 제외한다. 경고는 패널 최상단·원문 확인 필수, 주의는 확인 목록·근거 연결, 관찰은 추세·업종 위치로 표시한다. 수치는 현직자 확인 전 팀 가설이며 은행 등급·여신 판단을 대신하지 않는다. | H33: N-R14/N-R24/N-R36/N-R38/N-R39 | I33: N-F21/N-F34/N-F36/N-F37 | J33: N-U06/N-U12/N-U17
A34: 3.11 | B34: 직접 입력·출처·재계산 경로 확인 | C34: 김동민·최수인 | D34: 2.4, 3.3 | E34: 수기 입력·출처/시점 표시·확인 결과 | F34: 직접 입력의 원문/입력자/시점과 공시 수집 값을 구분하고 필수 입력·단위·누락/0·재계산을 확인한다. 내부 은행 자료를 수집하거나 임의 입력을 공식 원문으로 표시하지 않는다. | H34: N-R06/N-R27 | I34: N-F04/N-F24 | J34: N-U08
A35: 3.10 | B35: 기존 주석 화면에 업종 위험 패널·차트 연결 | C35: 김동민·오준탁 | D35: 3.9, 2.11 | E35: N-S04 위험 패널·업종 차트·원문 연결 | F35: 주석 확인 사항 단계에 패널을 둔다. 상단: 징후 요약 카드(단계별 건수, 색과 텍스트 병기), 핵심 지표 타일(당기·전기 대비·업종 중앙값), 5개년 스파크라인, 업종 내 위치 점 플롯(표본 부족 시 '비교 보류'). 업종별 차트: 제조(현금전환주기 분해 누적 막대, 매출·재고·매출채권 증가율 막대, 영업이익·영업CF·CAPEX 막대), 도소매(매출총이익률 라인, 매입채무·재고일수 라인, 리스 포함/제외 부채비율), 건설(PF 보증 만기 사다리, 계약자산 vs 매출 증가율, 우발채무÷자기자본 불릿, 원가율 추세), 부동산·임대(차입금 만기 사다리+금리, EBITDA 이자보상배율 1.0배 기준선, LTV 불릿, 임대율). 주석 근거 카드·보증 제공/수취 분리 표·만기 타임라인을 연결한다. 게이지·레이더는 쓰지 않고 결측은 '자료 없음' 회색으로 표시한다. | H35: N-R11/N-R27/N-R38/N-R39/N-R40/N-R43 | I35: N-F24/N-F36/N-F37/N-F38/N-F41 | J35: N-U17/N-U20
A36: 3.5 | B36: 현금흐름 괴리와 업종 비교 분석 | C36: 오준탁 | D36: 2.6, 3.1 | E36: 분석 결과와 적용 범위 | F36: 현금흐름과 이익 차이·차입/운전자본·기존 3개년 추세와 비교 분포·표본 한계를 설명한다. 패널 5개년 추세는 별도 시각화 기준으로 구분한다. | H36: N-R09/N-R10/N-R34/N-R35/N-R40 | I36: N-F07/N-F08/N-F32/N-F33/N-F38 | J36: N-U06/N-U16/N-U20
A37: 3.7 | B37: 핵심 분석과 확인 항목 통합 | C37: 김동민 | D37: 3.4, 3.6 | E37: 통합 대시보드 | F37: 계산·확인 항목·원문·담당자 메모를 연결한다. 규칙 단계·미래 확률·사용자 체크를 구분한다. | H37: N-R07/N-R14/N-R24/N-R25/N-R26/N-R27/N-R40 | I37: N-F05/N-F21/N-F22/N-F23/N-F24/N-F38
A38: 3.M2 | B38: 핵심 재무 기능 통합 완료 판단 | C38: 서종원·김동민 | D38: 3.5, 3.7, 2.4, 3.10, 3.11, 3.12 | E38: 핵심 기능 확인 기록 | F38: 정량 분석·직접 입력·업종 변경·위험 패널·차트의 제공 범위와 버전을 정리한다. 후보 임계값·미정·제공 보류를 화면에 표시한다. | H38: N-R06/N-R07/N-R32/N-R38/N-R39/N-R40 | I38: N-F04/N-F05/N-F30/N-F36/N-F37/N-F38
A39: 4.1 | B39: 주석 요약 형식과 확인 안내 정의 | C39: 김동혁 | D39: 2.3 | E39: 추출 필드·요약 형식 | F39: 공통 6범주/업종 추가 사전과 유형·방향·금액·통화·상태·기준일·원문 위치·검출 상태·검수 기록을 정의한다. 표/본문 중복·현재/전기·한도/잔액을 구분하고 코드는 N-U04/N-U18 합의 후 고정한다. | H39: N-R11/N-R12/N-R13/N-R14/N-R41/N-R42/N-R43 | I39: N-F09/N-F10/N-F11/N-F39/N-F40/N-F41 | J39: N-U04/N-U07/N-U18
A40: 4.2 | B40: 주석 위험 항목 추출과 AI 요약 | C40: 서종원 | D40: 4.1 | E40: 주석 추출·요약 결과 | F40: 공통/업종 규칙으로 얻은 구조화 주석을 근거 요약과 모델 입력에 공통 재사용한다. 일반 담보·대출약정을 자동으로 우발부채로 판정하지 않고, 검출 상태·금액 미기재를 0/정상으로 바꾸지 않는다. | H40: N-R11/N-R12/N-R13/N-R19/N-R41/N-R42/N-R43 | I40: N-F09/N-F10/N-F11/N-F15/N-F39/N-F40/N-F41 | J40: N-U04/N-U07/N-U18
A41: 4.8 | B41: 공통 주석 6범주 추출 규칙 구현 | C41: 김동민·최수인 | D41: 4.1, 2.11 | E41: 공통 검색어·추출 범위·저장 필드/버전 | F41: 감사의견/계속기업·차입 만기/재무약정·신용등급·담보 제공·소송/제재·부외거래/후속사건 6항목을 추출한다. 제목부터 다음 주석 번호/소제목 전까지 저장하고 다른 장 참조는 해당 위치를 다시 추출한다. 보증 제공/수취·원고/피고·현재/전기·한도/잔액·표/본문 중복과 교차참조를 구분한다. 일반 담보/대출을 자동 우발부채로 단정하지 않는다. | H41: N-R03/N-R11/N-R41/N-R43 | I41: N-F02/N-F09/N-F39/N-F41 | J41: N-U04/N-U18
A42: 4.3 | B42: 뉴스 수집 방식과 후보 기사 확보 | C42: 최수인 | D42: 없음 | E42: 뉴스 후보와 수집 조건 | F42: 기업·기간 식별과 매체 활용 조건 확인 | H42: N-R15 | I42: N-F12 | J42: N-U07
A43: 4.9 | B43: 4개 업종별 주석 추가 추출 규칙 구현 | C43: 김동민·오준탁·최수인 | D43: 4.8 | E43: 업종별 사전·추출 필드·원문 근거 | F43: 제조 재고/손상/개발비/공급자금융, 도소매 리스/매입처/점포, 건설 PF/계약자산/공사원가/분양, 임대 차입/투자부동산/임대율/보증금 규칙을 연결한다. 금액·한도·잔액·만기와 표 중복을 구분한다. | H43: N-R11/N-R42/N-R43 | I43: N-F09/N-F40/N-F41 | J43: N-U18
...

Sheet 이전 완료 이력
A1: 과거 문서 작성 완료 이력 — 현재 구현 완료가 아님
A4: ID | B4: 이전 작업 | C4: 당시 상태 | D4: 당시 진행률 | E4: 당시 기록 | F4: 현재 적용 경계
A5: 1.1 | B5: 기획안 v1.0 확정본 정리 | C5: 완료 | D5: 1 | E5: 기획안_LoanSight AI_v1.0.docx | F5: 재무·주석 결합 부도 예측, 역할·일정·확인·필수 기능을 반영한 v1.0 문서 확인. 기존 v1.0 완료 기록이며 이번 v2.0 반영 완료를 뜻하지 않는다.
A6: 1.2 | B6: 기획 발표자료 v0.2 초안 보존 | C6: 완료 | D6: 1 | E6: KB-Bridge_LoanSight AI_기획발표_v0.2.0.pptx | F6: 기존 11장·발표자 노트 초안 확인. v1.0 반영은 1.8에서 별도 수행. 기존 초안 보존 완료이며 최신 발표자료는 별도 검토한다.

Sheet 개정 이력
A1: 버전 | B1: 개정일 | C1: 내용 | D1: 개정자 | E1: 검토·승인
A2: v1.1 | B2: 2026.10.24 | C2: 이전 기준 반영 | D2: 김동혁 | E2: 미정
A3: v1.2 | B3: 2026.10.27 | C3: 상태·근거 변경 | D3: 최수인 | E3: 미정
A4: v1.3 | B4: 2026.10.28 | C4: v2.1 연계·내부 관리 분리·날짜 수식 보정 | D4: 미정 | E4: 미정
A5: v1.4 | B5: 2026.10.29 | C5: v2.3 통합 기획 반영·징후 기준 명확화·v2.1 확장 축소·CFS 우선/OFS 전환. 화면설계서 보존. | D5: 미정 | E5: 미정

Sheet 이번 개정 제외
A1: ID | B1: 사유
A2: 7.1 | B2: v2.3 현행 범위에서 제외. 이전 버전과 Notion 행은 이력으로 보존하며 ID 재사용 금지.
A3: 3.13 | B3: v2.3 현행 범위에서 제외. 이전 버전과 Notion 행은 이력으로 보존하며 ID 재사용 금지.
